Workbook
Name DL_Base: 'Direct Labor'!$D$16
Name Indirect_Labor_Total: 'Direct Labor'!$D$24
Name Fringe_Pool: 'Cost Pools'!$B$17
Name OH_Pool: 'Cost Pools'!$B$29
Name GA_Pool: 'Cost Pools'!$B$44

Sheet Instructions
A1: FEDERAL LEAD KIT — Indirect Rate Calculator
A2: Calculate your provisional fringe, overhead, and G&A rates from real cost data. Outputs the wrap rate and the bill rate you can drop into a proposal.
A4: WHAT THIS WORKBOOK DOES
A5: You probably know your loaded labor cost is more than the base salary. The hard part is putting a real number on it.
A6: This sheet does that math. You enter actual payroll and overhead numbers. It gives you back a fringe rate, an overhead rate, a G&A rate, and a wrap rate you can defend if DCAA asks.
A7: Build it once, refresh it every quarter, and you'll have a defensible price for the next RFP without scrambling.
A9: HOW TO USE IT — IN ORDER
A10: Step 1 | B10: Direct Labor tab | C10: List every employee who charges time to contracts. Annual salary and annual hours. That's your DL base.
A11: Step 2 | B11: Cost Pools tab | C11: Plug in fringe costs (taxes, health, retirement, PTO), overhead costs (rent, indirect labor, equipment), and G&A (executive salaries, accounting, BD).
A12: Step 3 | B12: Rate Summary tab | C12: Read the three pool rates, your wrap rate, and your bill rates per labor category. Change the target fee at the top to see the impact.
A13: Step 4 | B13: Help tab | C13: Read this before your first DCAA conversation. Definitions, typical ranges, and what auditors actually want to see.
A15: COLOR CODING
B16: Input | C16: You enter this. These cells drive every calculation downstream.
B17: Formula | C17: Auto-calculated. Leave it alone.
B18: Total | C18: Subtotal or section total. Always a formula.
B19: Warning | C19: Your rate is outside the typical range. Fix it or be ready to defend it.
B20: Reference | C20: Benchmark numbers for comparison. Not your data.
A22: WHEN TO REFRESH
B23: Quarterly | C23: Update direct labor and pool numbers from your books. Takes 30 minutes if your bookkeeper has clean categories.
B24: Before any cost proposal | C24: Pull actuals year-to-date and project forward. Submit a Forward Pricing Rate Agreement (FPRA) to DCAA if you do more than $50M in cost-type work.
B25: When you hire indirect staff | C25: A new HR or finance hire moves your overhead pool. The wrap rate shifts immediately, sometimes 2 to 4 points.
B26: When you change benefits | C26: Switched health plans, added 401(k) match, raised PTO. Fringe rate changes the next pay cycle.

Sheet Direct Labor
A1: DIRECT LABOR POOL — Employee Salary & Hours
A2: Enter each direct-charge employee. Overhead, fringe, and wrap calculations pull from this sheet.
A4: Employee Name / Position | B4: Clearance | C4: DL or Indirect? | D4: Annual Salary ($) | E4: Annual Hours | F4: Hourly DL Rate ($) | G4: Fringe Estimate ($) | H4: Annual DL Cost ($) | I4: Notes
A5: DIRECT EMPLOYEES (charge time to contracts)
A6: Program Manager | B6: Secret | C6: Direct | D6: 145000 | E6: 1860 | F6: =IFERROR(D6/E6,0) | G6: =D6*'Rate Summary'!$D$10 | H6: =D6+G6
A7: Senior Systems Engineer | B7: TS/SCI | C7: Direct | D7: 155000 | E7: 1860 | F7: =IFERROR(D7/E7,0) | G7: =D7*'Rate Summary'!$D$10 | H7: =D7+G7
A8: Systems Engineer (Mid) | B8: Secret | C8: Direct | D8: 115000 | E8: 1860 | F8: =IFERROR(D8/E8,0) | G8: =D8*'Rate Summary'!$D$10 | H8: =D8+G8
A9: Software Developer (Senior) | B9: Secret | C9: Direct | D9: 140000 | E9: 1860 | F9: =IFERROR(D9/E9,0) | G9: =D9*'Rate Summary'!$D$10 | H9: =D9+G9
A10: Software Developer (Mid) | B10: None | C10: Direct | D10: 105000 | E10: 1860 | F10: =IFERROR(D10/E10,0) | G10: =D10*'Rate Summary'!$D$10 | H10: =D10+G10
A11: Data Analyst | B11: Secret | C11: Direct | D11: 95000 | E11: 1860 | F11: =IFERROR(D11/E11,0) | G11: =D11*'Rate Summary'!$D$10 | H11: =D11+G11
A12: Technical Writer | B12: None | C12: Direct | D12: 78000 | E12: 1860 | F12: =IFERROR(D12/E12,0) | G12: =D12*'Rate Summary'!$D$10 | H12: =D12+G12
A13: Quality Assurance Lead | B13: Secret | C13: Direct | D13: 110000 | E13: 1860 | F13: =IFERROR(D13/E13,0) | G13: =D13*'Rate Summary'!$D$10 | H13: =D13+G13
A14: Project Coordinator | B14: None | C14: Direct | D14: 72000 | E14: 1860 | F14: =IFERROR(D14/E14,0) | G14: =D14*'Rate Summary'!$D$10 | H14: =D14+G14
A15: Subject Matter Expert (PT) | B15: TS/SCI | C15: Direct | D15: 90000 | E15: 960 | F15: =IFERROR(D15/E15,0) | G15: =D15*'Rate Summary'!$D$10 | H15: =D15+G15
A16: DIRECT LABOR TOTAL | D16: =SUM(D6:D15) | E16: =SUM(E6:E15) | F16: =IFERROR(D16/E16,0) | G16: =SUM(G6:G15) | H16: =SUM(H6:H15) | I16: ← Direct labor base
A18: INDIRECT / OVERHEAD LABOR (flows to OH pool, not DL base)
A19: Project Controls / Scheduler | B19: None | C19: Indirect | D19: 88000 | E19: 2080 | F19: =IFERROR(D19/E19,0) | G19: =D19*'Rate Summary'!$D$10 | H19: =D19+G19
A20: HR Manager | B20: None | C20: Indirect | D20: 95000 | E20: 2080 | F20: =IFERROR(D20/E20,0) | G20: =D20*'Rate Summary'!$D$10 | H20: =D20+G20
A21: Controller / Finance Manager | B21: None | C21: Indirect | D21: 125000 | E21: 2080 | F21: =IFERROR(D21/E21,0) | G21: =D21*'Rate Summary'!$D$10 | H21: =D21+G21
A22: IT Systems Administrator | B22: None | C22: Indirect | D22: 92000 | E22: 2080 | F22: =IFERROR(D22/E22,0) | G22: =D22*'Rate Summary'!$D$10 | H22: =D22+G22
A23: Facilities / Office Manager | B23: None | C23: Indirect | D23: 68000 | E23: 2080 | F23: =IFERROR(D23/E23,0) | G23: =D23*'Rate Summary'!$D$10 | H23: =D23+G23
A24: INDIRECT LABOR TOTAL | D24: =SUM(D19:D23) | E24: =SUM(E19:E23) | G24: =SUM(G19:G23) | H24: =SUM(H19:H23) | I24: → Flows to OH pool

Sheet Cost Pools
A1: INDIRECT COST POOLS — Fringe, Overhead & G&A
A2: Enter actual or estimated annual costs for each pool. Rates auto-calculate on the Rate Summary tab.
A4: FRINGE BENEFIT POOL — Base: Total Direct Labor Salaries
A5: FICA — Social Security (6.2% of wages up to $168,600) | B5: 75000
A6: FICA — Medicare (1.45% of all wages + 0.9% over $200K) | B6: 18000
A7: FUTA — Federal Unemployment (6% on first $7K, net ~0.6%) | B7: 600
A8: SUTA — State Unemployment (varies by state, 1–5%) | B8: 8500
A9: Health Insurance — Employer Contribution | B9: 95000
A10: Dental & Vision — Employer Contribution | B10: 11000
A11: Retirement / 401(k) Match | B11: 42000
A12: Paid Time Off (PTO) — accrual cost | B12: 56000
A13: Paid Holidays | B13: 38000
A14: Workers Compensation Insurance | B14: 7500
A15: Life / Disability Insurance | B15: 8500
A16: Other Fringe (commuter benefits, tuition, etc.) | B16: 5000
A17: TOTAL FRINGE POOL | B17: =SUM(B5:B16) | C17: → Fringe Rate = this ÷ DL Base
A19: OVERHEAD COST POOL — Base: Direct Labor Salaries
A20: Indirect Labor (auto-pulled from Direct Labor tab) | B20: =Indirect_Labor_Total | C20: Linked from Direct Labor tab
A21: Fringe on Indirect Labor | B21: =Indirect_Labor_Total*'Rate Summary'!$D$10 | C21: Linked from Direct Labor tab
A22: Facilities — Rent, Utilities, Janitorial (contract-supporting space) | B22: 96000
A23: Equipment — Computers, Software licenses for DL employees | B23: 28000
A24: Subcontractor Oversight (if not direct-charged) | B24: 12000
A25: Travel — Indirect (site visits, not billable to specific contracts) | B25: 14000
A26: Training — Technical (job-specific, not G&A) | B26: 9500
A27: Recruiting — Direct employee sourcing | B27: 8000
A28: Other Overhead | B28: 6000
A29: TOTAL OVERHEAD POOL | B29: =SUM(B20:B28) | C29: → Overhead Rate = this ÷ DL Base
A31: G&A (GENERAL & ADMINISTRATIVE) COST POOL — Base: Total Cost Input
A32: Executive / Owner Salaries (non-billable portion) | B32: 220000
A33: Fringe on G&A Labor | B33: 66000
A34: Accounting & Finance | B34: 38000
A35: Legal & Compliance | B35: 22000
A36: Business Development & Proposal (non-overhead BD) | B36: 45000
A37: General IT / Corporate Systems | B37: 18000
A38: Corporate Facilities (not allocated to OH) | B38: 24000
A39: Professional Memberships & Subscriptions | B39: 9000
A40: Corporate Insurance (D&O, E&O, General Liability) | B40: 28000
A41: Corporate Travel | B41: 14000
A42: Bid & Proposal (B&P) Costs | B42: 32000
A43: Other G&A | B43: 6000
...

Sheet Rate Summary
A1: INDIRECT RATE SUMMARY & WRAP RATE CALCULATOR
A2: Pulls from Direct Labor and Cost Pools tabs. Change the fee, escalation, and fringe override below.
A4: RATE INPUTS & ASSUMPTIONS
B6: Target Fee / Profit Rate | D6: 0.08 | E6: Used in bill rate and full wrap. CPFF typical 6–10%. FFP varies.
B7: Annual Escalation Rate (Year 2+) | D7: 0.03 | E7: Salary escalation for option years. 2–4% is normal for GovCon.
B8: Fringe Rate (override — optional) | E8: Leave blank to auto-calculate from Cost Pools.
A9: CALCULATED INDIRECT RATES
B10: Direct Labor Base (annual salaries) | C10: =DL_Base | D10: =IF(ISNUMBER(D8),D8,IFERROR(Fringe_Pool/DL_Base,0)) | E10: Fringe Pool ÷ DL Base. Typical: 25–35%.
B11: Overhead Rate | C11: =OH_Pool | D11: =IFERROR(OH_Pool/DL_Base,0) | E11: Overhead Pool ÷ DL Base. Typical: 10–25%.
B12: Total Cost Input (G&A base) | C12: =DL_Base*(1+D10+D11) | E12: DL × (1 + Fringe + OH). Base used for G&A.
B13: G&A Rate | C13: =GA_Pool | D13: =IFERROR(GA_Pool/C12,0) | E13: G&A Pool ÷ Total Cost Input. Typical: 10–20%.
A15: WRAP RATE & BILL RATE MULTIPLIERS
B16: Wrap Rate (excl. fee) | D16: =(1+D10)*(1+D11)*(1+D13) | E16: Multiply by base DL hourly to get fully-loaded cost.
B17: Full Wrap Rate (incl. fee) | D17: =D16*(1+D6) | E17: Your bill multiplier. Multiply by hourly DL rate to get proposed price.
A19: BILL RATE TABLE — By Labor Category
B20: Labor Category | C20: Base Salary ($) | D20: Hourly DL Rate | E20: Fringe-Loaded | F20: OH-Loaded | G20: G&A-Loaded | H20: Bill Rate (incl. fee)
B21: Program Manager | C21: 145000 | D21: =C21/1860 | E21: =D21*(1+$D$10) | F21: =E21*(1+$D$11) | G21: =F21*(1+$D$13) | H21: =G21*(1+$D$6)
B22: Senior Systems Engineer | C22: 155000 | D22: =C22/1860 | E22: =D22*(1+$D$10) | F22: =E22*(1+$D$11) | G22: =F22*(1+$D$13) | H22: =G22*(1+$D$6)
B23: Systems Engineer (Mid) | C23: 115000 | D23: =C23/1860 | E23: =D23*(1+$D$10) | F23: =E23*(1+$D$11) | G23: =F23*(1+$D$13) | H23: =G23*(1+$D$6)
B24: Software Developer (Senior) | C24: 140000 | D24: =C24/1860 | E24: =D24*(1+$D$10) | F24: =E24*(1+$D$11) | G24: =F24*(1+$D$13) | H24: =G24*(1+$D$6)
B25: Software Developer (Mid) | C25: 105000 | D25: =C25/1860 | E25: =D25*(1+$D$10) | F25: =E25*(1+$D$11) | G25: =F25*(1+$D$13) | H25: =G25*(1+$D$6)
B26: Data Analyst | C26: 95000 | D26: =C26/1860 | E26: =D26*(1+$D$10) | F26: =E26*(1+$D$11) | G26: =F26*(1+$D$13) | H26: =G26*(1+$D$6)
B27: Technical Writer | C27: 78000 | D27: =C27/1860 | E27: =D27*(1+$D$10) | F27: =E27*(1+$D$11) | G27: =F27*(1+$D$13) | H27: =G27*(1+$D$6)
B28: QA Lead | C28: 110000 | D28: =C28/1860 | E28: =D28*(1+$D$10) | F28: =E28*(1+$D$11) | G28: =F28*(1+$D$13) | H28: =G28*(1+$D$6)
A31: RATE HEALTH CHECKS
B32: Rate | C32: Your Value | D32: Typical Low | E32: Typical High | F32: Status
B33: Fringe Rate | C33: =D10 | D33: 0.25 | E33: 0.35 | F33: =IF(C33<D33,"BELOW typical — investigate",IF(C33>E33,"ABOVE typical — review","WITHIN typical range"))
B34: Overhead Rate | C34: =D11 | D34: 0.1 | E34: 0.25 | F34: =IF(C34<D34,"BELOW typical — investigate",IF(C34>E34,"ABOVE typical — review","WITHIN typical range"))
B35: G&A Rate | C35: =D13 | D35: 0.1 | E35: 0.2 | F35: =IF(C35<D35,"BELOW typical — investigate",IF(C35>E35,"ABOVE typical — review","WITHIN typical range"))
B36: Total Wrap Rate (excl. fee) | C36: =D16 | D36: 1.5 | E36: 2.2 | F36: =IF(C36<D36,"BELOW typical — investigate",IF(C36>E36,"ABOVE typical — review","WITHIN typical range"))
A38: DCAA NOTE: Rates outside the typical range aren't automatically a problem. They have to be supported. Write a one-page cost accounting policy that explains how you allocate each pool, keep the source data, and submit it with your cost proposal. That's what auditors actually ask for.

Sheet Help
A1: HELP — Definitions, Typical Ranges, DCAA Survival
A3: KEY DEFINITIONS
B4: Direct Labor (DL) Base | C4: Total wages paid to people performing direct contract work. Every indirect rate is calculated as a percentage of this base. Get this wrong and everything downstream is wrong.
B5: Fringe Rate | C5: Fringe ÷ Total DL Salaries. Covers payroll taxes (FICA, FUTA, SUTA), health insurance, retirement, PTO, workers comp. Typical: 25–35%. Below 22% usually means you're missing PTO or 401(k) accruals.
B6: Overhead Rate | C6: Overhead Pool ÷ Direct Labor Base. Covers indirect labor (supervisors, QA, admin supporting contracts), facilities, indirect materials. Typical: 10–25%. Pure-services firms run lower; firms with facilities run higher.
B7: G&A Rate | C7: G&A Pool ÷ Total Cost Input. Covers executive salaries, accounting, BD, legal, corporate insurance. Typical: 10–20%. New firms can hit 25–30% in year one because the executive salary is spread over a tiny revenue base.
B8: Wrap Rate | C8: (1 + Fringe) × (1 + OH) × (1 + G&A). The multiplier you apply to base DL wages to get fully-loaded cost before fee. Typical: 1.50–2.20.
B9: Bill Rate | C9: Wrap Rate × (1 + Fee) × (Base Salary ÷ Annual Hours). Your all-in cost-per-hour proposal rate for a labor category.
B10: Forward Pricing Rate | C10: Your estimated indirect rates for a future period, submitted to DCAA. Used in Cost Accounting Standards (CAS) environments. Required once you hit $50M in cost-type work.
B11: Provisional Rate | C11: An interim rate you and the government agree on while actuals are still being accumulated. DCAA audits and trues up at year-end. If your provisionals are way off, you'll write a check or get one.
A13: TYPICAL RANGES BY COMPANY TYPE
B14: Small services firm (1-25 staff) | C14: Fringe 28-32%, OH 15-22%, G&A 12-18%, Wrap 1.65-1.95
B15: Mid services firm (25-150 staff) | C15: Fringe 28-35%, OH 18-28%, G&A 8-14%, Wrap 1.80-2.15
B16: Hardware / facilities-heavy | C16: Fringe 25-32%, OH 30-50%, G&A 8-12%, Wrap 2.00-2.50
B17: Pure R&D / SBIR | C17: Fringe 28-35%, OH 50-100%+, G&A 15-25%, Wrap 2.50-4.00
B18: Staff augmentation / time-and-materials | C18: Fringe 25-30%, OH 8-15%, G&A 8-12%, Wrap 1.40-1.65
A20: DCAA SURVIVAL CHECKLIST
B21: Written cost accounting policy | C21: One page. How you decide what's direct vs indirect, which pool a cost goes into, what allocation base each pool uses. Sign and date it.
B22: Timekeeping that ties to charge codes | C22: Every employee, every day, every hour, against a specific charge code. Daily entry. Supervisor approval. DCAA will pull samples.
B23: Job cost accounting in your books | C23: Your accounting system (QuickBooks Enterprise, Unanet, Deltek, Procas) needs to roll up costs by contract and by indirect pool. Stock QuickBooks Online does not pass DCAA review.
B24: Indirect pool documentation | C24: For every line in your overhead and G&A pools, you need an invoice or payroll record. No "estimated" costs.
B25: Quarterly true-up | C25: Compare provisional rates to actuals. If you're off by more than 10%, file a revised provisional rate proposal.
B26: Year-end Incurred Cost Submission (ICS) | C26: Due 6 months after fiscal year end. Required if you have any cost-type contracts. Forms ICE-format. DCAA audits these on a 3-5 year cycle.
A28: COMMON MISTAKES THAT KILL PROPOSALS
B29: Bill rate too low | C29: You forgot to escalate option years, or your fringe rate is missing PTO and 401(k). The contracting officer notices and your evaluator either rejects the price as unrealistic or flags it for cost realism review.
B30: Bill rate too high | C30: Your wrap is 2.4 in a market where the average is 1.85. You lose to the cheaper proposal. Either trim your G&A pool (often bloated executive salary) or rethink whether this is the right market for you.
B31: Mixing direct and indirect costs | C31: Charging the same person's time to both direct projects and overhead in the same week without a clear allocation methodology. DCAA disallows the cost and you eat it.
B32: No timecards | C32: If you can't show daily time entries against charge codes, DCAA will disallow your direct labor and bill you back. Companies have lost everything over this.
B33: Allocating BD to G&A | C33: Selling to the government is part of normal business. But BD chasing a specific contract isn't allowable — it's unallowable B&P that has to come out of fee, not get billed back through G&A.
