Workbook
Name opp_name: 'Decision Matrix'!$C$4
Name sol_num: 'Decision Matrix'!$F$4
Name agency: 'Decision Matrix'!$C$5
Name naics: 'Decision Matrix'!$F$5
Name value: 'Decision Matrix'!$C$6
Name setaside: 'Decision Matrix'!$F$6
Name pop: 'Decision Matrix'!$C$7
Name ctype: 'Decision Matrix'!$F$7
Name due_date: 'Decision Matrix'!$C$8
Name incumbent_known: 'Decision Matrix'!$F$8
Name evaluator: 'Decision Matrix'!$C$9
Name clearance_req: 'Decision Matrix'!$F$9
Name eval_date: 'Decision Matrix'!$C$10
Name teaming: 'Decision Matrix'!$F$10
Name total_weighted: 'Decision Matrix'!$E$46
Name total_max: 'Decision Matrix'!$F$46
Name score_pct: 'Decision Matrix'!$E$47
Name recommendation: 'Decision Matrix'!$E$48

Sheet Decision Matrix
A1: BID / NO-BID DECISION MATRIX
A2: CapturePilot - Capture intelligence for government contractors
B4: Opportunity Name | E4: Solicitation #
B5: Agency / Office | E5: NAICS Code
B6: Contract Value (USD) | E6: Set-Aside Type
B7: Period of Performance | E7: Contract Type
B8: Proposal Due Date | E8: Incumbent Known?
B9: Evaluated By | E9: Clearance Required?
B10: Date Evaluated | E10: Teaming Partner?
A14: # | B14: SCORING CRITERION | C14: WEIGHT (1-5) | D14: SCORE (0-5) | E14: WEIGHTED SCORE | F14: MAX POSSIBLE | G14: NOTES / EVIDENCE
A15: STRATEGIC FIT - Does this opportunity belong in our pipeline at all?
A16: 1 | B16: NAICS code alignment with our core capabilities | C16: 5 | E16: =IF(D16="",0,C16*D16) | F16: =IF(D16="",0,C16*5)
A17: 2 | B17: Opportunity type matches our target contract vehicles | C17: 4 | E17: =IF(D17="",0,C17*D17) | F17: =IF(D17="",0,C17*5)
A18: 3 | B18: Agency is in our target agency list | C18: 4 | E18: =IF(D18="",0,C18*D18) | F18: =IF(D18="",0,C18*5)
A19: 4 | B19: Geographic location is feasible for our team | C19: 3 | E19: =IF(D19="",0,C19*D19) | F19: =IF(D19="",0,C19*5)
A20: 5 | B20: Opportunity supports long-term capture strategy | C20: 4 | E20: =IF(D20="",0,C20*D20) | F20: =IF(D20="",0,C20*5)
A21: COMPETITIVE POSITION - Can we actually win against the field that's likely to show up?
A22: 6 | B22: We have prior relationship with KO / COR / end user | C22: 5 | E22: =IF(D22="",0,C22*D22) | F22: =IF(D22="",0,C22*5)
A23: 7 | B23: We are the incumbent or have teamed with incumbent | C23: 4 | E23: =IF(D23="",0,C23*D23) | F23: =IF(D23="",0,C23*5)
A24: 8 | B24: We can differentiate from likely competitors | C24: 4 | E24: =IF(D24="",0,C24*D24) | F24: =IF(D24="",0,C24*5)
A25: 9 | B25: We have relevant past performance (direct match) | C25: 5 | E25: =IF(D25="",0,C25*D25) | F25: =IF(D25="",0,C25*5)
A26: 10 | B26: Set-aside type favors our certifications | C26: 3 | E26: =IF(D26="",0,C26*D26) | F26: =IF(D26="",0,C26*5)
A27: CAPTURE READINESS - Can we mount a credible response without breaking the company?
A28: 11 | B28: We have the personnel / capacity to respond in time | C28: 5 | E28: =IF(D28="",0,C28*D28) | F28: =IF(D28="",0,C28*5)
A29: 12 | B29: We have or can assemble the right team / subs | C29: 4 | E29: =IF(D29="",0,C29*D29) | F29: =IF(D29="",0,C29*5)
A30: 13 | B30: Required clearances are held or obtainable | C30: 4 | E30: =IF(D30="",0,C30*D30) | F30: =IF(D30="",0,C30*5)
A31: 14 | B31: Capture resources (proposal manager, writer) available | C31: 3 | E31: =IF(D31="",0,C31*D31) | F31: =IF(D31="",0,C31*5)
A32: 15 | B32: Solution / technical approach is clear to us now | C32: 4 | E32: =IF(D32="",0,C32*D32) | F32: =IF(D32="",0,C32*5)
A33: WIN PROBABILITY FACTORS - The intangibles that determine PWin once you actually submit.
A34: 16 | B34: We have intelligence on the customer's priorities | C34: 4 | E34: =IF(D34="",0,C34*D34) | F34: =IF(D34="",0,C34*5)
A35: 17 | B35: We can price competitively (LPTA or best-value) | C35: 5 | E35: =IF(D35="",0,C35*D35) | F35: =IF(D35="",0,C35*5)
A36: 18 | B36: No disqualifying compliance gaps (reps & certs) | C36: 5 | E36: =IF(D36="",0,C36*D36) | F36: =IF(D36="",0,C36*5)
A37: 19 | B37: Evaluation criteria favor our strengths | C37: 4 | E37: =IF(D37="",0,C37*D37) | F37: =IF(D37="",0,C37*5)
A38: 20 | B38: We have attended industry days / responded to RFIs | C38: 3 | E38: =IF(D38="",0,C38*D38) | F38: =IF(D38="",0,C38*5)
A39: BUSINESS VALUE - Even if we can win, is this the right use of B&P dollars?
A40: 21 | B40: Contract value meets our revenue threshold | C40: 4 | E40: =IF(D40="",0,C40*D40) | F40: =IF(D40="",0,C40*5)
A41: 22 | B41: Win opens door to larger follow-on work | C41: 4 | E41: =IF(D41="",0,C41*D41) | F41: =IF(D41="",0,C41*5)
A42: 23 | B42: Profit margin is acceptable given effort required | C42: 5 | E42: =IF(D42="",0,C42*D42) | F42: =IF(D42="",0,C42*5)
A43: 24 | B43: Strategic value (agency expansion, certification use) | C43: 3 | E43: =IF(D43="",0,C43*D43) | F43: =IF(D43="",0,C43*5)
A44: 25 | B44: Resource investment is proportional to potential | C44: 4 | E44: =IF(D44="",0,C44*D44) | F44: =IF(D44="",0,C44*5)
...

Sheet Summary
A1: BID / NO-BID SUMMARY
A3: Opportunity Name | B3: =IFERROR(opp_name,"")
A4: Agency / Office | B4: =IFERROR(agency,"")
A5: Solicitation # | B5: =IFERROR(sol_num,"")
A6: NAICS Code | B6: =IFERROR(naics,"")
A7: Set-Aside | B7: =IFERROR(setaside,"")
A8: Contract Type | B8: =IFERROR(ctype,"")
A9: Contract Value | B9: =IFERROR(value,"")
A10: Period of Performance | B10: =IFERROR(pop,"")
A11: Proposal Due Date | B11: =IFERROR(due_date,"")
A12: Evaluated By | B12: =IFERROR(evaluator,"")
A13: Date Evaluated | B13: =IFERROR(eval_date,"")
A15: CATEGORY BREAKDOWN
A16: Category | B16: What it measures | C16: Weighted | D16: Max | E16: Pct | F16: Status
A17: STRATEGIC FIT | B17: Does this opportunity belong in our pipeline at all? | C17: =SUM('Decision Matrix'!E16:E20) | D17: =SUM('Decision Matrix'!F16:F20) | E17: =IFERROR(C17/D17,0) | F17: =IF(D17=0,"Not scored",IF(E17>=0.6,"Strong",IF(E17>=0.4,"Mixed","Weak")))
A18: COMPETITIVE POSITION | B18: Can we actually win against the field that's likely to show up? | C18: =SUM('Decision Matrix'!E22:E26) | D18: =SUM('Decision Matrix'!F22:F26) | E18: =IFERROR(C18/D18,0) | F18: =IF(D18=0,"Not scored",IF(E18>=0.6,"Strong",IF(E18>=0.4,"Mixed","Weak")))
A19: CAPTURE READINESS | B19: Can we mount a credible response without breaking the company? | C19: =SUM('Decision Matrix'!E28:E32) | D19: =SUM('Decision Matrix'!F28:F32) | E19: =IFERROR(C19/D19,0) | F19: =IF(D19=0,"Not scored",IF(E19>=0.6,"Strong",IF(E19>=0.4,"Mixed","Weak")))
A20: WIN PROBABILITY FACTORS | B20: The intangibles that determine PWin once you actually submit. | C20: =SUM('Decision Matrix'!E34:E38) | D20: =SUM('Decision Matrix'!F34:F38) | E20: =IFERROR(C20/D20,0) | F20: =IF(D20=0,"Not scored",IF(E20>=0.6,"Strong",IF(E20>=0.4,"Mixed","Weak")))
A21: BUSINESS VALUE | B21: Even if we can win, is this the right use of B&P dollars? | C21: =SUM('Decision Matrix'!E40:E44) | D21: =SUM('Decision Matrix'!F40:F44) | E21: =IFERROR(C21/D21,0) | F21: =IF(D21=0,"Not scored",IF(E21>=0.6,"Strong",IF(E21>=0.4,"Mixed","Weak")))
A23: OVERALL RECOMMENDATION
A24: Total weighted score | B24: =total_weighted | C24: Max possible | D24: =total_max | E24: Score % | F24: =score_pct
A25: =recommendation
A27: CapturePilot Federal Lead Kit - capturepilot.com - 04 Bid/No-Bid Decision Matrix

Sheet Scoring Guide
A1: SCORING GUIDE - How to rate each criterion
A3: SCORE DEFINITIONS - applies to every criterion
B4: 5 | C4: STRONG | D4: We clearly meet or exceed this criterion. Documented evidence is on file (signed CPARs, named POC, executed teaming agreement, etc.).
B5: 4 | C5: GOOD | D5: We generally meet this with minor gaps. We're not bluffing in the proposal.
B6: 3 | C6: FAIR | D6: We partially meet this. Closing the gap takes real effort and the gap is visible to evaluators.
B7: 2 | C7: WEAK | D7: We barely meet this. The gap is a real bid risk. We will have to mitigate in the proposal.
B8: 1 | C8: POOR | D8: We don't meet this or evidence is absent. Honest answer: if this matters, we shouldn't bid.
B9: 0 | C9: N/A | D9: Not applicable to this opportunity. Excluded from both numerator and denominator.
A11: CRITERION GUIDE - what to consider when scoring
A12: # | C12: Criterion | D12: Wt | E12: What to consider
A13: STRATEGIC FIT
A14: 1 | C14: NAICS code alignment with our core capabilities | D14: 5 | E14: Do we hold this NAICS on our SAM.gov registration? Is it a primary code, not an add-on?
A15: 2 | C15: Opportunity type matches our target contract vehicles | D15: 4 | E15: FFP / T&M / CPFF / IDIQ — does the contract type match how we usually deliver?
A16: 3 | C16: Agency is in our target agency list | D16: 4 | E16: Is this one of our top-five target agencies? Do we have an existing relationship anywhere in the org?
A17: 4 | C17: Geographic location is feasible for our team | D17: 3 | E17: Can we deliver on-site if required? Do we have staff within reasonable distance of the place of performance?
A18: 5 | C18: Opportunity supports long-term capture strategy | D18: 4 | E18: Does winning this open a vehicle, agency, or follow-on we actually want to be in for the next five years?
A19: COMPETITIVE POSITION
A20: 6 | C20: We have prior relationship with KO / COR / end user | D20: 5 | E20: Have we met the KO, COR, or program office in the last 12 months? Not just a LinkedIn connection — a real conversation.
A21: 7 | C21: We are the incumbent or have teamed with incumbent | D21: 4 | E21: Incumbency or teaming with the incumbent is worth roughly 20 PWin points. If neither, score this honestly.
A22: 8 | C22: We can differentiate from likely competitors | D22: 4 | E22: Can we name 3 discriminators competitors cannot match? Write them in the notes column.
A23: 9 | C23: We have relevant past performance (direct match) | D23: 5 | E23: Do we have 2+ references at similar scope, dollar value, and agency type? Federal past performance beats commercial.
A24: 10 | C24: Set-aside type favors our certifications | D24: 3 | E24: Does our 8(a) / HUBZone / SDVOSB / WOSB status match the set-aside? If unrestricted, we're competing against everyone.
A25: CAPTURE READINESS
A26: 11 | C26: We have the personnel / capacity to respond in time | D26: 5 | E26: Can we staff a proposal team without pulling people off paying work? B&P costs are real.
A27: 12 | C27: We have or can assemble the right team / subs | D27: 4 | E27: Do we have signed teaming agreements, or at least established sub relationships we can mobilize this week?
A28: 13 | C28: Required clearances are held or obtainable | D28: 4 | E28: Do key staff already hold Secret / TS / TS-SCI? Don't bid 'we'll get them cleared' — that almost never works.
A29: 14 | C29: Capture resources (proposal manager, writer) available | D29: 3 | E29: Do we have a proposal manager, technical writer, and graphics support? Consultant or in-house both count.
A30: 15 | C30: Solution / technical approach is clear to us now | D30: 4 | E30: Could we sketch the technical approach on a napkin today? If not, we're going to learn on the proposal — that's expensive.
A31: WIN PROBABILITY FACTORS
A32: 16 | C32: We have intelligence on the customer's priorities | D32: 4 | E32: Do we know their stated priorities, pain points, and how the incumbent is doing? FOIA, FPDS, and conversations are all valid sources.
A33: 17 | C33: We can price competitively (LPTA or best-value) | D33: 5 | E33: Can we price within plus or minus 5% of the likely winning price? Use FPDS history for similar work as your anchor.
A34: 18 | C34: No disqualifying compliance gaps (reps & certs) | D34: 5 | E34: Reps and certs current? CMMC level adequate? No outstanding debarments, suspensions, or pending size protests?
A35: 19 | C35: Evaluation criteria favor our strengths | D35: 4 | E35: Look at Section M. Do the technical, management, and past performance weights play to our strengths or our gaps?
A36: 20 | C36: We have attended industry days / responded to RFIs | D36: 3 | E36: Did we attend the industry day or respond to the sources sought? Shaping happens 6-18 months before solicitation.
A37: BUSINESS VALUE
A38: 21 | C38: Contract value meets our revenue threshold | D38: 4 | E38: Is the total contract value above the minimum we set in our annual plan? Don't bid 50K opportunities if our floor is 250K.
A39: 22 | C39: Win opens door to larger follow-on work | D39: 4 | E39: Is this a gateway contract with likely option years, task orders, or follow-on awards? Small first deals can be worth it.
A40: 23 | C40: Profit margin is acceptable given effort required | D40: 5 | E40: After B&P costs, indirect costs, and delivery cost, can we still hit our target margin? Run the numbers, don't guess.
A41: 24 | C41: Strategic value (agency expansion, certification use) | D41: 3 | E41: Does winning expand our past performance portfolio into a new agency, vehicle, or capability we want to grow?
A42: 25 | C42: Resource investment is proportional to potential | D42: 4 | E42: Is the B&P investment reasonable given expected TCV? Spending 60K to chase a 200K one-year deal almost never makes sense.

Sheet Instructions
A1: INSTRUCTIONS - How to use this workbook
A3: Why this exists
B4: Most small businesses lose money by bidding everything that looks vaguely relevant. B&P costs run 1-5% of contract value, and a bad bid costs you the chance to chase a good one. This matrix forces a 10-minute structured conversation before you commit.
B5: It's built around 25 criteria split into 5 categories. Each criterion has a weight (1-5, how much it matters) and a score (0-5, how strong we are on it). The output is a weighted percentage and a Bid / Review / No-Bid recommendation.
A6: Step-by-step
B7: 1 | C7: Fill in the opportunity metadata at the top of the Decision Matrix tab. Solicitation number, agency, value, due date, set-aside, contract type, NAICS. The Summary tab pulls from these cells, so they're worth getting right.
B8: 2 | C8: Adjust weights in column C if a criterion matters more or less for your business. The defaults are tuned for a typical small federal contractor. If you sell only to DoD, bump 'target agency' from 4 to 5. If you don't do classified work, drop 'clearances held' to 1.
B9: 3 | C9: Score each criterion 0-5 using the dropdown in column D. Use the Scoring Guide tab for definitions. Leave it blank if you genuinely haven't formed an opinion yet (blank rows are excluded from the percentage).
B10: 4 | C10: Use the Notes column to record evidence. 'Met COR Lisa Chang at AFCEA West, March 2026.' 'No relevant past performance above 500K.' 'Incumbent is Booz, two task orders, $8.2M total.' This is what makes the matrix defensible six months from now when someone asks why you bid.
B11: 5 | C11: Read the recommendation. Below 40% means no bid - the math is telling you to spend B&P somewhere else. 40-60% means review with the team - usually there's one or two weak categories that, if fixed, would make this a real bid. 60% plus is a bid - move it into your capture pipeline.
A12: Reading the thresholds
B13: The 40/60 thresholds aren't magic. They came from looking at hundreds of small business bid decisions and noticing that opportunities scoring below 40% on a weighted criteria model lose more than 90% of the time. Opportunities scoring above 60% win roughly 30-50%, which is high for federal work.
B14: If you're consistently bidding things in the 40-50% range, your win rate will live around 10-15% and your B&P spend will eat your margin. That's the actual problem this tool solves.
A15: When to ignore the score
B16: Three legitimate reasons to bid a 35% opportunity: (1) it's a strategic must-win for an agency relationship you've been building for years, (2) the customer has signaled they will award to you and the solicitation is mostly procedural, (3) you're using it to shape - the bid itself is part of intel-gathering for a larger follow-on.
B17: If none of those three apply and the score is below 40%, don't bid. Spend the time on capture for a better target.
A18: Weight tuning
B19: Weights are 1 (low) to 5 (critical). The default profile assumes a typical 8(a) or small business services contractor going after agencies they already know. Two profiles worth considering:
B20: Hardware / product reseller: bump Pricing competitiveness to 5, drop Customer intelligence to 3, drop Past performance to 4. Price wins more often than relationships in product.
B21: Niche professional services: bump Past performance to 5, bump Differentiation to 5, drop Set-aside fit to 2. Your edge is expertise, not certification.
A22: Tabs in this workbook
B23: 1 | C23: Decision Matrix - the working sheet. Enter scores here.
B24: 2 | C24: Summary - one-page output. Print this for the bid review meeting.
B25: 3 | C25: Scoring Guide - definitions for every criterion. Send this to anyone scoring with you so you're using the same scale.
B26: 4 | C26: Instructions - this page.
A27: If you change the criteria
B28: Adding or removing criteria breaks the per-category roll-up on the Summary tab (it expects 5 items per category). Adjust the SUM ranges on the Summary tab if you restructure. Adjusting weights is safe at any time - the formulas use whatever is in column C.
A30: CapturePilot Federal Lead Kit - capturepilot.com - 04 Bid/No-Bid Decision Matrix

Sheet Worked Example
A1: WORKED EXAMPLE - GSA Janitorial Services, 8(a) sole source
A3: Hypothetical: small janitorial firm with 8(a), HUBZone-adjacent, three years of federal past performance at FBI and SSA. NAICS 561720. Considering a 2.4M GSA 8(a) sole-source opportunity, 5-year base + options, place of performance Atlanta. They have a small office in Decatur, so geography works.
A5: # | B5: CRITERION | C5: WT | D5: SCORE | E5: WEIGHTED | F5: MAX | G5: WHY
A6: STRATEGIC FIT
A7: 1 | B7: NAICS code alignment with our core capabilities | C7: 5 | D7: 5 | E7: 25 | F7: 25 | G7: Primary NAICS, held on SAM for four years.
A8: 2 | B8: Opportunity type matches our target contract vehicles | C8: 4 | D8: 4 | E8: 16 | F8: 20 | G8: FFP services - exactly what we deliver.
A9: 3 | B9: Agency is in our target agency list | C9: 4 | D9: 5 | E9: 20 | F9: 20 | G9: GSA is top agency on our list, KO knows us.
A10: 4 | B10: Geographic location is feasible for our team | C10: 3 | D10: 5 | E10: 15 | F10: 15 | G10: Atlanta office, 30-minute drive to site.
A11: 5 | B11: Opportunity supports long-term capture strategy | C11: 4 | D11: 4 | E11: 16 | F11: 20 | G11: Wins us a five-year footprint at GSA Region 4.
A12: COMPETITIVE POSITION
A13: 6 | B13: We have prior relationship with KO / COR / end user | C13: 5 | D13: 4 | E13: 20 | F13: 25 | G13: Have met the COR twice, but new KO assigned last month.
A14: 7 | B14: We are the incumbent or have teamed with incumbent | C14: 4 | D14: 1 | E14: 4 | F14: 20 | G14: Not incumbent - ABC Services Inc. holds it.
A15: 8 | B15: We can differentiate from likely competitors | C15: 4 | D15: 3 | E15: 12 | F15: 20 | G15: Two real discriminators: green cleaning cert, local supervisor.
A16: 9 | B16: We have relevant past performance (direct match) | C16: 5 | D16: 4 | E16: 20 | F16: 25 | G16: Three CPARs at similar scope and dollar value.
A17: 10 | B17: Set-aside type favors our certifications | C17: 3 | D17: 5 | E17: 15 | F17: 15 | G17: 8(a) sole source - we're the only one allowed to bid.
A18: CAPTURE READINESS
A19: 11 | B19: We have the personnel / capacity to respond in time | C19: 5 | D19: 4 | E19: 20 | F19: 25 | G19: Have the people; one project wraps next month.
A20: 12 | B20: We have or can assemble the right team / subs | C20: 4 | D20: 5 | E20: 20 | F20: 20 | G20: Subs already vetted from prior FBI contract.
A21: 13 | B21: Required clearances are held or obtainable | C21: 4 | D21: 0 | E21: 0 | F21: 0 | G21: No clearance required - N/A.
A22: 14 | B22: Capture resources (proposal manager, writer) available | C22: 3 | D22: 4 | E22: 12 | F22: 15 | G22: Have an external proposal consultant on retainer.
A23: 15 | B23: Solution / technical approach is clear to us now | C23: 4 | D23: 5 | E23: 20 | F23: 20 | G23: Janitorial is bread-and-butter; approach is obvious.
A24: WIN PROBABILITY FACTORS
A25: 16 | B25: We have intelligence on the customer's priorities | C25: 4 | D25: 4 | E25: 16 | F25: 20 | G25: Customer wants quality + green cleaning - we know this from RFI.
A26: 17 | B26: We can price competitively (LPTA or best-value) | C26: 5 | D26: 4 | E26: 20 | F26: 25 | G26: Within 3% of FPDS comp prices for similar SOWs.
A27: 18 | B27: No disqualifying compliance gaps (reps & certs) | C27: 5 | D27: 5 | E27: 25 | F27: 25 | G27: Reps and certs current as of last month.
A28: 19 | B28: Evaluation criteria favor our strengths | C28: 4 | D28: 4 | E28: 16 | F28: 20 | G28: 60/40 technical/price - we're stronger on technical.
A29: 20 | B29: We have attended industry days / responded to RFIs | C29: 3 | D29: 2 | E29: 6 | F29: 15 | G29: Did not attend the industry day - missed it.
A30: BUSINESS VALUE
A31: 21 | B31: Contract value meets our revenue threshold | C31: 4 | D31: 5 | E31: 20 | F31: 20 | G31: 2.4M is well above our 500K floor.
A32: 22 | B32: Win opens door to larger follow-on work | C32: 4 | D32: 4 | E32: 16 | F32: 20 | G32: GSA wide-area BPA likely to follow.
A33: 23 | B33: Profit margin is acceptable given effort required | C33: 5 | D33: 4 | E33: 20 | F33: 25 | G33: Margin penciled at 14% after B&P.
A34: 24 | B34: Strategic value (agency expansion, certification use) | C34: 3 | D34: 4 | E34: 12 | F34: 15 | G34: Opens GSA Region 4 for follow-on work.
A35: 25 | B35: Resource investment is proportional to potential | C35: 4 | D35: 5 | E35: 20 | F35: 20 | G35: B&P estimate is 18K against 2.4M TCV - proportionate.
A37: TOTAL | E37: 406 | F37: 490 | G37: 82.9%
A38: RECOMMENDATION: BID - Strong go signal
A40: What this tells us: the firm is strong on strategic fit, capture readiness, and business value. The one weakness is incumbency (criterion 7) - someone else holds it. The 8(a) sole-source structure neutralizes that risk. The missed industry day is a minor B&P penalty, not a deal-killer. Bid it.
A42: CapturePilot Federal Lead Kit - capturepilot.com - 04 Bid/No-Bid Decision Matrix
