Workbook
Name BusinessName: Inputs!$C$4
Name OwnerNames: Inputs!$C$5
Name PrimaryNAICS: Inputs!$C$6
Name BusinessStart: Inputs!$C$7
Name EvalDate: Inputs!$C$8
Name MetResponses: Inputs!$C$12:$C$42
Name RiskLevels: Inputs!$D$12:$D$42
Name TotalWeight: Calc!$E$29
Name TotalScore: Calc!$F$29
Name ReadinessPct: Calc!$G$29

Sheet Inputs
A1: 8(a) BD PROGRAM — CERTIFICATION SELF-ASSESSMENT
A2: CapturePilot · SBA Section 8(a) eligibility quick-check. Not a substitute for legal review or formal SBA decision.
B4: Business Name
B5: Owner Name(s)
B6: Primary NAICS Code
B7: Business Start Date
B8: Evaluation Date
A10: # | B10: ELIGIBILITY REQUIREMENT | C10: MET? (Y/N/?) | D10: RISK | E10: NOTES / EVIDENCE
A11: SMALL BUSINESS STATUS
A12: 1 | B12: Business qualifies as small under SBA size standards for its primary NAICS code | D12: HIGH
A13: 2 | B13: Business is at least 51% unconditionally owned by socially + economically disadvantaged individual(s) | D13: HIGH
A14: 3 | B14: Business is NOT publicly traded (publicly traded companies are ineligible) | D14: HIGH
A15: 4 | B15: Combined personal net worth of all disadvantaged owners is under $850,000 (excluding equity in primary residence and 8(a) firm) | D15: HIGH
A16: 5 | B16: Adjusted gross income averaged under $400,000 over the last 3 years | D16: HIGH
A17: OWNER ELIGIBILITY — SOCIAL DISADVANTAGE
A18: 6 | B18: Owner is a member of a presumed disadvantaged group (Black, Hispanic, Asian Pacific, Subcontinent Asian, or Native American) | D18: HIGH
A19: 7 | B19: OR owner can demonstrate social disadvantage by a preponderance of evidence (documented chronic racial or ethnic prejudice) | D19: HIGH
A20: 8 | B20: Owner is a U.S. citizen | D20: HIGH
A21: OWNER ELIGIBILITY — ECONOMIC DISADVANTAGE
A22: 9 | B22: Total assets of all disadvantaged owners combined are under $6,500,000 | D22: HIGH
A23: 10 | B23: Personal net worth of each disadvantaged owner is under $850,000 at time of application | D23: HIGH
A24: 11 | B24: Owner has not accumulated wealth inconsistent with a claim of economic disadvantage | D24: MEDIUM
A25: MANAGEMENT & DAILY OPERATIONS
A26: 12 | B26: A socially and economically disadvantaged owner controls management and daily operations | D26: HIGH
A27: 13 | B27: Owner holds the highest officer position (President, CEO, or Managing Member) | D27: HIGH
A28: 14 | B28: No non-disadvantaged individuals hold blocking shares or board seats that can override owner decisions | D28: HIGH
A29: 15 | B29: Disadvantaged owner is actively involved in the business (not a passive investor) | D29: HIGH
A30: BUSINESS POTENTIAL
A31: 16 | B31: Business has been in operation for at least 2 years (or owner can show 2+ years of management experience) | D31: MEDIUM
A32: 17 | B32: Business shows reasonable prospects for success (revenue, contracts, or pipeline) | D32: MEDIUM
A33: 18 | B33: Business is NOT currently debarred, suspended, or proposed for debarment | D33: HIGH
A34: 19 | B34: Business has no outstanding federal tax liens or unresolved SBA loan defaults | D34: MEDIUM
A35: 8(a) PROGRAM TERM LIMITS
A36: 20 | B36: Business has NOT previously participated in the 8(a) program (one-time, 9-year term) | D36: HIGH
A37: 21 | B37: Business revenues have NOT exceeded the 8(a) graduation threshold for 4 consecutive years (~$27.5M services) | D37: MEDIUM
A38: ADMINISTRATIVE REQUIREMENTS
A39: 22 | B39: Business is registered and active on SAM.gov | D39: HIGH
A40: 23 | B40: All required tax returns have been filed for the last 3 years | D40: HIGH
A41: 24 | B41: Business bank accounts are in the company name only | D41: MEDIUM
A42: 25 | B42: No felony convictions or pending criminal matters involving the owner | D42: HIGH
...

Sheet Calc
A1: CALCULATION SHEET — Per-item scoring (do not edit)
A2: # | B2: Requirement | C2: Met? | D2: Risk | E2: Weight | F2: Score | G2: Status
A3: 1 | B3: =Inputs!B12 | C3: =Inputs!C12 | D3: =Inputs!D12 | E3: =IF(D3="HIGH",3,IF(D3="MEDIUM",2,1)) | F3: =IF(C3="Y",E3,IF(C3="?",E3/2,0)) | G3: =IF(C3="Y","Pass",IF(C3="N",IF(D3="HIGH","Fail","Risk"),IF(C3="?","Open","—")))
A4: 2 | B4: =Inputs!B13 | C4: =Inputs!C13 | D4: =Inputs!D13 | E4: =IF(D4="HIGH",3,IF(D4="MEDIUM",2,1)) | F4: =IF(C4="Y",E4,IF(C4="?",E4/2,0)) | G4: =IF(C4="Y","Pass",IF(C4="N",IF(D4="HIGH","Fail","Risk"),IF(C4="?","Open","—")))
A5: 3 | B5: =Inputs!B14 | C5: =Inputs!C14 | D5: =Inputs!D14 | E5: =IF(D5="HIGH",3,IF(D5="MEDIUM",2,1)) | F5: =IF(C5="Y",E5,IF(C5="?",E5/2,0)) | G5: =IF(C5="Y","Pass",IF(C5="N",IF(D5="HIGH","Fail","Risk"),IF(C5="?","Open","—")))
A6: 4 | B6: =Inputs!B15 | C6: =Inputs!C15 | D6: =Inputs!D15 | E6: =IF(D6="HIGH",3,IF(D6="MEDIUM",2,1)) | F6: =IF(C6="Y",E6,IF(C6="?",E6/2,0)) | G6: =IF(C6="Y","Pass",IF(C6="N",IF(D6="HIGH","Fail","Risk"),IF(C6="?","Open","—")))
A7: 5 | B7: =Inputs!B16 | C7: =Inputs!C16 | D7: =Inputs!D16 | E7: =IF(D7="HIGH",3,IF(D7="MEDIUM",2,1)) | F7: =IF(C7="Y",E7,IF(C7="?",E7/2,0)) | G7: =IF(C7="Y","Pass",IF(C7="N",IF(D7="HIGH","Fail","Risk"),IF(C7="?","Open","—")))
A8: 6 | B8: =Inputs!B18 | C8: =Inputs!C18 | D8: =Inputs!D18 | E8: =IF(D8="HIGH",3,IF(D8="MEDIUM",2,1)) | F8: =IF(C8="Y",E8,IF(C8="?",E8/2,0)) | G8: =IF(C8="Y","Pass",IF(C8="N",IF(D8="HIGH","Fail","Risk"),IF(C8="?","Open","—")))
A9: 7 | B9: =Inputs!B19 | C9: =Inputs!C19 | D9: =Inputs!D19 | E9: =IF(D9="HIGH",3,IF(D9="MEDIUM",2,1)) | F9: =IF(C9="Y",E9,IF(C9="?",E9/2,0)) | G9: =IF(C9="Y","Pass",IF(C9="N",IF(D9="HIGH","Fail","Risk"),IF(C9="?","Open","—")))
A10: 8 | B10: =Inputs!B20 | C10: =Inputs!C20 | D10: =Inputs!D20 | E10: =IF(D10="HIGH",3,IF(D10="MEDIUM",2,1)) | F10: =IF(C10="Y",E10,IF(C10="?",E10/2,0)) | G10: =IF(C10="Y","Pass",IF(C10="N",IF(D10="HIGH","Fail","Risk"),IF(C10="?","Open","—")))
A11: 9 | B11: =Inputs!B22 | C11: =Inputs!C22 | D11: =Inputs!D22 | E11: =IF(D11="HIGH",3,IF(D11="MEDIUM",2,1)) | F11: =IF(C11="Y",E11,IF(C11="?",E11/2,0)) | G11: =IF(C11="Y","Pass",IF(C11="N",IF(D11="HIGH","Fail","Risk"),IF(C11="?","Open","—")))
A12: 10 | B12: =Inputs!B23 | C12: =Inputs!C23 | D12: =Inputs!D23 | E12: =IF(D12="HIGH",3,IF(D12="MEDIUM",2,1)) | F12: =IF(C12="Y",E12,IF(C12="?",E12/2,0)) | G12: =IF(C12="Y","Pass",IF(C12="N",IF(D12="HIGH","Fail","Risk"),IF(C12="?","Open","—")))
A13: 11 | B13: =Inputs!B24 | C13: =Inputs!C24 | D13: =Inputs!D24 | E13: =IF(D13="HIGH",3,IF(D13="MEDIUM",2,1)) | F13: =IF(C13="Y",E13,IF(C13="?",E13/2,0)) | G13: =IF(C13="Y","Pass",IF(C13="N",IF(D13="HIGH","Fail","Risk"),IF(C13="?","Open","—")))
A14: 12 | B14: =Inputs!B26 | C14: =Inputs!C26 | D14: =Inputs!D26 | E14: =IF(D14="HIGH",3,IF(D14="MEDIUM",2,1)) | F14: =IF(C14="Y",E14,IF(C14="?",E14/2,0)) | G14: =IF(C14="Y","Pass",IF(C14="N",IF(D14="HIGH","Fail","Risk"),IF(C14="?","Open","—")))
A15: 13 | B15: =Inputs!B27 | C15: =Inputs!C27 | D15: =Inputs!D27 | E15: =IF(D15="HIGH",3,IF(D15="MEDIUM",2,1)) | F15: =IF(C15="Y",E15,IF(C15="?",E15/2,0)) | G15: =IF(C15="Y","Pass",IF(C15="N",IF(D15="HIGH","Fail","Risk"),IF(C15="?","Open","—")))
A16: 14 | B16: =Inputs!B28 | C16: =Inputs!C28 | D16: =Inputs!D28 | E16: =IF(D16="HIGH",3,IF(D16="MEDIUM",2,1)) | F16: =IF(C16="Y",E16,IF(C16="?",E16/2,0)) | G16: =IF(C16="Y","Pass",IF(C16="N",IF(D16="HIGH","Fail","Risk"),IF(C16="?","Open","—")))
A17: 15 | B17: =Inputs!B29 | C17: =Inputs!C29 | D17: =Inputs!D29 | E17: =IF(D17="HIGH",3,IF(D17="MEDIUM",2,1)) | F17: =IF(C17="Y",E17,IF(C17="?",E17/2,0)) | G17: =IF(C17="Y","Pass",IF(C17="N",IF(D17="HIGH","Fail","Risk"),IF(C17="?","Open","—")))
A18: 16 | B18: =Inputs!B31 | C18: =Inputs!C31 | D18: =Inputs!D31 | E18: =IF(D18="HIGH",3,IF(D18="MEDIUM",2,1)) | F18: =IF(C18="Y",E18,IF(C18="?",E18/2,0)) | G18: =IF(C18="Y","Pass",IF(C18="N",IF(D18="HIGH","Fail","Risk"),IF(C18="?","Open","—")))
A19: 17 | B19: =Inputs!B32 | C19: =Inputs!C32 | D19: =Inputs!D32 | E19: =IF(D19="HIGH",3,IF(D19="MEDIUM",2,1)) | F19: =IF(C19="Y",E19,IF(C19="?",E19/2,0)) | G19: =IF(C19="Y","Pass",IF(C19="N",IF(D19="HIGH","Fail","Risk"),IF(C19="?","Open","—")))
A20: 18 | B20: =Inputs!B33 | C20: =Inputs!C33 | D20: =Inputs!D33 | E20: =IF(D20="HIGH",3,IF(D20="MEDIUM",2,1)) | F20: =IF(C20="Y",E20,IF(C20="?",E20/2,0)) | G20: =IF(C20="Y","Pass",IF(C20="N",IF(D20="HIGH","Fail","Risk"),IF(C20="?","Open","—")))
A21: 19 | B21: =Inputs!B34 | C21: =Inputs!C34 | D21: =Inputs!D34 | E21: =IF(D21="HIGH",3,IF(D21="MEDIUM",2,1)) | F21: =IF(C21="Y",E21,IF(C21="?",E21/2,0)) | G21: =IF(C21="Y","Pass",IF(C21="N",IF(D21="HIGH","Fail","Risk"),IF(C21="?","Open","—")))
A22: 20 | B22: =Inputs!B36 | C22: =Inputs!C36 | D22: =Inputs!D36 | E22: =IF(D22="HIGH",3,IF(D22="MEDIUM",2,1)) | F22: =IF(C22="Y",E22,IF(C22="?",E22/2,0)) | G22: =IF(C22="Y","Pass",IF(C22="N",IF(D22="HIGH","Fail","Risk"),IF(C22="?","Open","—")))
A23: 21 | B23: =Inputs!B37 | C23: =Inputs!C37 | D23: =Inputs!D37 | E23: =IF(D23="HIGH",3,IF(D23="MEDIUM",2,1)) | F23: =IF(C23="Y",E23,IF(C23="?",E23/2,0)) | G23: =IF(C23="Y","Pass",IF(C23="N",IF(D23="HIGH","Fail","Risk"),IF(C23="?","Open","—")))
A24: 22 | B24: =Inputs!B39 | C24: =Inputs!C39 | D24: =Inputs!D39 | E24: =IF(D24="HIGH",3,IF(D24="MEDIUM",2,1)) | F24: =IF(C24="Y",E24,IF(C24="?",E24/2,0)) | G24: =IF(C24="Y","Pass",IF(C24="N",IF(D24="HIGH","Fail","Risk"),IF(C24="?","Open","—")))
A25: 23 | B25: =Inputs!B40 | C25: =Inputs!C40 | D25: =Inputs!D40 | E25: =IF(D25="HIGH",3,IF(D25="MEDIUM",2,1)) | F25: =IF(C25="Y",E25,IF(C25="?",E25/2,0)) | G25: =IF(C25="Y","Pass",IF(C25="N",IF(D25="HIGH","Fail","Risk"),IF(C25="?","Open","—")))
A26: 24 | B26: =Inputs!B41 | C26: =Inputs!C41 | D26: =Inputs!D41 | E26: =IF(D26="HIGH",3,IF(D26="MEDIUM",2,1)) | F26: =IF(C26="Y",E26,IF(C26="?",E26/2,0)) | G26: =IF(C26="Y","Pass",IF(C26="N",IF(D26="HIGH","Fail","Risk"),IF(C26="?","Open","—")))
A27: 25 | B27: =Inputs!B42 | C27: =Inputs!C42 | D27: =Inputs!D42 | E27: =IF(D27="HIGH",3,IF(D27="MEDIUM",2,1)) | F27: =IF(C27="Y",E27,IF(C27="?",E27/2,0)) | G27: =IF(C27="Y","Pass",IF(C27="N",IF(D27="HIGH","Fail","Risk"),IF(C27="?","Open","—")))
A29: TOTALS | E29: =SUM(E3:E27) | F29: =SUM(F3:F27) | G29: =IF(E29=0,0,F29/E29)

Sheet Summary
A1: 8(a) BD PROGRAM — READINESS SUMMARY
B3: Business | D3: =IF(BusinessName="","(not set)",BusinessName)
B4: Owner(s) | D4: =IF(OwnerNames="","(not set)",OwnerNames)
B5: Evaluated | D5: =IF(EvalDate="","(not set)",EvalDate)
B7: COUNTS
B8: Requirements met (Y) | E8: =COUNTIF(MetResponses,"Y")
B9: Requirements not met (N) | E9: =COUNTIF(MetResponses,"N")
B10: Open / unknown (?) | E10: =COUNTIF(MetResponses,"?")
B11: Unanswered (blank) | E11: =COUNTBLANK(MetResponses)
B12: High-risk fails (N + HIGH) | E12: =SUMPRODUCT((MetResponses="N")*(RiskLevels="HIGH"))
B13: Medium-risk fails (N + MEDIUM) | E13: =SUMPRODUCT((MetResponses="N")*(RiskLevels="MEDIUM"))
B14: Total items | E14: =COUNTA(RiskLevels)
B16: WEIGHTED READINESS SCORE
B17: Readiness (weighted: HIGH=3 / MEDIUM=2 / LOW=1; Y=full, ?=half, N=0) | E17: =ReadinessPct
B19: PRELIMINARY VERDICT
B20: =IF(SUMPRODUCT((MetResponses="N")*(RiskLevels="HIGH"))>0,"INELIGIBLE: one or more high-risk requirements failed. Fix the N + HIGH items on the Inputs tab before applying.",IF(COUNTBLANK(MetResponses)+COUNTIF(MetResponses,"?")>5,"INCOMPLETE: too many open or unanswered items. Resolve the ? entries first.",IF(ReadinessPct>=0.85,"LIKELY ELIGIBLE: schedule a free pre-application meeting with your SBA District Office and a GovCon attorney before submitting through certify.sba.gov.",IF(ReadinessPct>=0.6,"POSSIBLE: you have most pieces in place. Close the N and ? items on the Inputs tab before you start the formal application.","NOT READY: significant gaps. Focus first on small-business status, owner control, and the $850K net worth test."))))
B22: NEXT ACTIONS
B23: High-risk gaps to close | C23: =IF(SUMPRODUCT((MetResponses="N")*(RiskLevels="HIGH"))>0,"Fix every N + HIGH row on the Inputs tab. Most common: net worth above $850K, owner does not control daily operations, or business is not yet 2 years old.","No high-risk gaps. Good.")
B24: Documentation to gather | C24: ="3 years of business + personal tax returns; current personal financial statement; operating agreement / bylaws; org chart with titles; SAM.gov registration confirmation; bank statements in firm name."
B25: Submission path | C25: ="Create MySBA account at certify.sba.gov. Application review target is 90 days. If declined, request reconsideration within 45 days or appeal to OHA."
B26: Free help available | C26: ="Book a pre-application meeting with your SBA District Office Business Opportunity Specialist (BOS). It is free and they will pre-screen your application before you submit."
B28: This summary uses your inputs only — it is not an official SBA decision. Thresholds change. Verify the personal net worth limit ($850K), total assets cap ($6.5M), and 3-year average AGI limit ($400K) at sba.gov before applying. The 8(a) program is a one-time, 9-year participation. Get a GovCon attorney or your SBA District Office to review before you submit through certify.sba.gov.

Sheet Instructions
A1: HOW TO USE THIS WORKBOOK
B3: WHAT THIS WORKBOOK DOES
B4: It walks you through the 25 questions the SBA reviews when deciding if your firm qualifies for the 8(a) Business Development program. Answer each row with Y, N, or ? — the Summary tab gives you a weighted readiness score and a plain-English verdict.
B6: TABS
B7: 1) Inputs — fill in your business info at the top, then mark each requirement Y / N / ? and add notes. 2) Calc — automatic per-item scoring. Do not edit. 3) Summary — counts, weighted readiness percentage, verdict, and next actions. 4) Instructions — this tab. 5) Program Reference — thresholds, presumed groups, application process.
B9: HOW THE SCORE WORKS
B10: Each requirement carries a risk weight: HIGH = 3, MEDIUM = 2, LOW = 1. Y earns the full weight; ? earns half; N earns zero. Readiness = total earned / total possible. The verdict adds two hard gates: any N on a HIGH item flips the result to INELIGIBLE, and more than 5 blanks or ? flips it to INCOMPLETE.
B12: THRESHOLDS YOU NEED TO HIT
B13: • Personal net worth: under $850,000 (excludes primary home equity and 8(a) firm value). • Total assets: under $6,500,000 combined for all disadvantaged owners. • Adjusted gross income: 3-year average under $400,000. • Ownership: at least 51% unconditionally held by socially + economically disadvantaged individual(s). • Operation: at least 2 years in business, or owner shows 2+ years of management experience. • Citizenship: owner is a U.S. citizen. • Track record: business is active on SAM.gov with 3 years of filed tax returns.
B15: BEFORE YOU APPLY
B16: 1) Run this checklist and fix every N on a HIGH-risk row. 2) Pull 3 years of business and personal tax returns plus current personal financial statements. 3) Get your operating agreement, org chart, and signature authority docs in one folder. 4) Confirm SAM.gov is active and the primary NAICS is correct. 5) Write the social disadvantage narrative if you are not in a presumed group. 6) Book the free pre-application meeting with your SBA District Office BOS before you submit. They will tell you what is missing.
B18: COMMON REJECTION REASONS
B19: • Owner does not hold the highest title (President / CEO / Managing Member). • Net worth crosses $850K at time of application. • Business is younger than 2 years and the owner cannot show qualifying management experience. • Non-presumed-group owner files no social disadvantage narrative. • Bank accounts or major assets are in the owner's name, not the firm's. • Tax returns and application financials disagree.
... B28: This worksheet is informational. Thresholds change. The SBA decides eligibility, not this file. Verify at sba.gov before applying and consult a GovCon attorney before you submit through certify.sba.gov.

Sheet Program Reference
A1: SBA 8(a) BD PROGRAM — KEY FACTS & APPLICATION GUIDE
B3: WHAT IS THE 8(a) PROGRAM?
B4: The SBA 8(a) Business Development program is a one-time, 9-year program that gives eligible small businesses access to sole-source and set-aside federal contracts. Years 1-4 (Developmental Stage) focus on capacity building. Years 5-9 (Transitional Stage) require an increasing share of competitive (non-sole-source) wins.
B6: KEY THRESHOLDS (current)
B7: • Personal net worth limit: $850,000 (excludes primary residence and 8(a) firm equity) • Total assets limit: $6,500,000 • Adjusted gross income limit: $400,000 average over 3 years • Sole-source award limit: $4.5M (services) / $7M (manufacturing) • Competitive threshold: contracts above the sole-source limit must be competed within 8(a) • Program term: 9 years total (4 developmental + 5 transitional), one-time only
B9: PRESUMED SOCIALLY DISADVANTAGED GROUPS
B10: • Black Americans • Hispanic Americans • Asian Pacific Americans (Japanese, Chinese, Filipino, Korean, Vietnamese, Laotian, Cambodian, Taiwanese, Burmese, Thai, Malaysian, Indonesian, Singaporean) • Subcontinent Asian Americans (Indian, Pakistani, Bangladeshi, Sri Lankan, Nepalese, Bhutanese) • Native Americans (including Alaska Natives and Native Hawaiians) Owners outside these groups must submit documented evidence of chronic racial or ethnic prejudice (a social disadvantage narrative).
B12: APPLICATION PROCESS
B13: 1) Register or verify active SAM.gov registration with correct NAICS codes. 2) Pull 3 years of tax returns (business + personal) and current financial statements. 3) Prepare ownership and control docs: operating agreement, org chart, signature authority proof. 4) Create MySBA account at certify.sba.gov and start the online application. 5) Write a personal social disadvantage narrative (only required if you are not in a presumed group). 6) Submit. SBA District Office target review is 90 days. 7) If declined: reconsideration request within 45 days, or appeal to OHA (Office of Hearings and Appeals).
B15: COMMON REJECTION REASONS
B16: • Owner does not control daily operations or hold the highest title. • Net worth crosses $850K at time of application. • Business younger than 2 years without qualifying management experience. • No social disadvantage evidence (for non-presumed groups). • Bank accounts or assets not clearly in the firm's name. • Tax returns and application financials disagree.
B18: BENEFITS ONCE CERTIFIED
B19: • Sole-source awards up to $4.5M (services) without competition • Priority for 8(a) set-aside competitions • Advantages on certain GWAC vehicles (8(a) STARS III, OASIS SB) • Access to the SBA Mentor-Protégé Program • Business development support from SBA District Offices • Tribes, ANCs, and NHOs can award sole-source 8(a) contracts of any size
... B22: • Use CapturePilot to find 8(a) set-aside opportunities in your NAICS codes • Filter Set-Aside Type = 8(a) in the Opportunities view • Watch SAM.gov Contracting Opportunities daily for sole-source notices • Contact your SBA District Office to book a free pre-application meeting • Reference: sba.gov/8a | certify.sba.gov | sam.gov
