Workbook
Name StatusRange: Checklist!$E$6:$E$45
Name RequiredRange: Checklist!$D$6:$D$45
Name KickoffDate: Timeline!$C$5

Sheet Dashboard
A1: CAPTUREPILOT · SAM Pre-Reg Dashboard
A2: Live readiness score · auto-calculated from your Checklist tab
A4: Update statuses on the Checklist tab. This page recalculates instantly.
B6: TOTAL ITEMS | C6: DONE | D6: TO GET | E6: BLOCKED / N/A | F6: READINESS
B7: =COUNTA(Checklist!D6:D45) | C7: =COUNTIF(Checklist!E6:E45,"Done") | D7: =COUNTIF(Checklist!E6:E45,"Need to get") | E7: =COUNTIF(Checklist!E6:E45,"N/A") | F7: =IFERROR(COUNTIF(Checklist!E6:E45,"Done")/COUNTA(Checklist!D6:D45),0)
B10: REQUIRED-ONLY COMPLETION (excludes optional + if-applicable rows)
B11: =IFERROR(COUNTIFS(Checklist!D6:D45,"Required",Checklist!E6:E45,"Done")/COUNTIF(Checklist!D6:D45,"Required"),0)
B13: PER-SECTION BREAKDOWN
B14: Section | C14: Items | D14: Done | E14: Remaining | F14: % Complete
B15: 1. Legal & Business Identity | C15: =COUNTA(Checklist!D6:D12) | D15: =COUNTIF(Checklist!E6:E12,"Done") | E15: =COUNTIF(Checklist!E6:E12,"Need to get") | F15: =IFERROR(COUNTIF(Checklist!E6:E12,"Done")/COUNTA(Checklist!D6:D12),0)
B16: 2. Points of Contact | C16: =COUNTA(Checklist!D14:D17) | D16: =COUNTIF(Checklist!E14:E17,"Done") | E16: =COUNTIF(Checklist!E14:E17,"Need to get") | F16: =IFERROR(COUNTIF(Checklist!E14:E17,"Done")/COUNTA(Checklist!D14:D17),0)
B17: 3. NAICS Codes | C17: =COUNTA(Checklist!D19:D21) | D17: =COUNTIF(Checklist!E19:E21,"Done") | E17: =COUNTIF(Checklist!E19:E21,"Need to get") | F17: =IFERROR(COUNTIF(Checklist!E19:E21,"Done")/COUNTA(Checklist!D19:D21),0)
B18: 4. Banking & Payment (EFT) | C18: =COUNTA(Checklist!D23:D26) | D18: =COUNTIF(Checklist!E23:E26,"Done") | E18: =COUNTIF(Checklist!E23:E26,"Need to get") | F18: =IFERROR(COUNTIF(Checklist!E23:E26,"Done")/COUNTA(Checklist!D23:D26),0)
B19: 5. Set-Aside Certifications | C19: =COUNTA(Checklist!D28:D31) | D19: =COUNTIF(Checklist!E28:E31,"Done") | E19: =COUNTIF(Checklist!E28:E31,"Need to get") | F19: =IFERROR(COUNTIF(Checklist!E28:E31,"Done")/COUNTA(Checklist!D28:D31),0)
B20: 6. login.gov Account | C20: =COUNTA(Checklist!D33:D36) | D20: =COUNTIF(Checklist!E33:E36,"Done") | E20: =COUNTIF(Checklist!E33:E36,"Need to get") | F20: =IFERROR(COUNTIF(Checklist!E33:E36,"Done")/COUNTA(Checklist!D33:D36),0)
B21: 7. Notarized Letter | C21: =COUNTA(Checklist!D38:D41) | D21: =COUNTIF(Checklist!E38:E41,"Done") | E21: =COUNTIF(Checklist!E38:E41,"Need to get") | F21: =IFERROR(COUNTIF(Checklist!E38:E41,"Done")/COUNTA(Checklist!D38:D41),0)
B22: 8. Optional / Products Sellers | C22: =COUNTA(Checklist!D43:D45) | D22: =COUNTIF(Checklist!E43:E45,"Done") | E22: =COUNTIF(Checklist!E43:E45,"Need to get") | F22: =IFERROR(COUNTIF(Checklist!E43:E45,"Done")/COUNTA(Checklist!D43:D45),0)
B24: OVERALL STATUS
B25: =IF(COUNTIFS(Checklist!D6:D45,"Required",Checklist!E6:E45,"Done")=COUNTIF(Checklist!D6:D45,"Required"),"READY — open sam.gov and start your registration",IF(COUNTIFS(Checklist!D6:D45,"Required",Checklist!E6:E45,"Done")/COUNTIF(Checklist!D6:D45,"Required")>=0.7,"ALMOST THERE — finish the last few required items first","NOT YET — keep collecting documents. Do not start SAM.gov until required items are Done."))

Sheet Checklist
A1: CAPTUREPILOT · SAM.gov Pre-Registration Checklist
A2: Gather everything below BEFORE opening SAM.gov · Federal Launch Kit Doc 01-B · capturepilot.com
A3: Heads up: SAM.gov registration is free. Never pay a third party. Starting without these documents causes mid-registration errors that lose your session.
A5: # | B5: Item to Gather | C5: Where to Find It · Notes | D5: Required? | E5: My Status | F5: Owner / Due Date
A6: SECTION 1 — Legal & Business Identity
A7: 1 | B7: Exact legal business name from IRS records | C7: Pull from IRS Letter CP 575 or 147C. Copy character-for-character including commas, periods, spacing. | D7: Required
A8: 2 | B8: EIN / TIN (Employer Identification Number) | C8: From your IRS EIN confirmation letter. Call IRS at 1-800-829-4933 if you need a copy (Letter 147C). | D8: Required
A9: 3 | B9: Business start date (legal formation date) | C9: The date on your Secretary of State incorporation documents. NOT the date you started operations. | D9: Required
A10: 4 | B10: Physical business street address | C10: PO Boxes are not accepted. Use a registered agent address if you need privacy protection. | D10: Required
A11: 5 | B11: Fiscal year end date | C11: Usually December 31. Must match your tax year end. | D11: Required
A12: 6 | B12: Business entity type | C12: LLC, S-Corp, C-Corp, Sole Proprietor, Partnership, Nonprofit, etc. | D12: Required
A13: 7 | B13: State of incorporation / formation | C13: Found on your Secretary of State registration documents. | D13: Required
A14: SECTION 2 — Points of Contact (3 Required)
A15: 8 | B15: Entity Administrator: name and email | C15: Person managing the SAM.gov account. Must match the email on your login.gov account. Use a monitored inbox. | D15: Required
A16: 9 | B16: Government Business POC: name, title, phone, email | C16: Primary contracting contact. Appears publicly in your registration. Contracting Officers will reach you here. | D16: Required
A17: 10 | B17: Electronic Business POC: name, title, phone, email | C17: Contact for invoicing and electronic transactions. Can be the same person as the Government Business POC. | D17: Required
A18: 11 | B18: Accounts Receivable POC: name, title, phone, email | C18: Payment processing contact. For small businesses, all three POC roles can be the same person. | D18: Required
A19: SECTION 3 — NAICS Codes (Industry Classification)
A20: 12 | B20: Primary NAICS code (6-digit) | C20: The code for your main line of business. Look up at census.gov/naics or use CapturePilot NAICS Picker (Doc 01-C). | D20: Required
A21: 13 | B21: SBA size standard for your primary NAICS | C21: Check sba.gov/size-standards. Determines if you qualify as Small. Based on revenue or employees depending on industry. | D21: Required
A22: 14 | B22: Additional NAICS codes for other services | C22: Add every relevant code. Agencies filter by NAICS when searching vendors. More codes mean more visibility. | D22: Recommended
A23: SECTION 4 — Banking & Payment (EFT)
A24: 15 | B24: Bank routing number (9-digit ABA number) | C24: Found on your checks (first 9 digits at the bottom). Read each digit back before entering. | D24: Required
A25: 16 | B25: Bank account number | C25: Business checking or savings account. Errors cause payment failures after award. | D25: Required
A26: 17 | B26: Account type (checking or savings) | C26: Typically checking for business accounts. | D26: Required
A27: 18 | B27: Bank name, full address, and phone number | C27: Legal bank name and branch address. Not just "Chase" — the full entity name. | D27: Required
A28: SECTION 5 — Set-Aside Certifications (If Applicable)
A29: 19 | B29: 8(a) certification letter (SBA-issued) | C29: Only if you already have active 8(a) status. Apply at certify.sba.gov after SAM activation if you qualify. | D29: If applicable
A30: 20 | B30: HUBZone certification letter (SBA-issued) | C30: SBA-certified only. Verify your office and employees are in a HUBZone at certify.sba.gov. | D30: If applicable
A31: 21 | B31: WOSB / EDWOSB certification letter (SBA-issued) | C31: Women-owned. SBA certification required since 2020 — self-certification is no longer accepted. | D31: If applicable
A32: 22 | B32: VOSB / SDVOSB VA CVE verification letter | C32: Veteran-owned or service-disabled veteran-owned. CVE verified at veteransmallbizce.va.gov. | D32: If applicable
A33: SECTION 6 — login.gov Account (Complete Before SAM.gov)
A34: 23 | B34: login.gov account created | C34: Use your Entity Administrator email. Same address that will own your SAM.gov account. | D34: Required
A35: 24 | B35: 2-Factor Authentication (2FA) enabled | C35: Use an authenticator app (Google Authenticator or Authy). Not SMS, which can fail mid-registration. | D35: Required
A36: 25 | B36: Identity verification completed on login.gov | C36: Requires a government-issued photo ID (driver's license or passport). Takes about 10 minutes. | D36: Required
A37: 26 | B37: Backup codes downloaded and stored safely | C37: If you lose your 2FA device, backup codes are your only recovery option. Store offline. | D37: Required
A38: SECTION 7 — Notarized Entity Administrator Letter
A39: 27 | B39: GSA Notarized Letter template downloaded | C39: Search "Entity Registration Notarized Letter" at fsd.gov. Only the official GSA template is accepted. | D39: Required
A40: 28 | B40: Company letterhead prepared (logo + address) | C40: The letter must be on official company letterhead. Create one in Word or Canva if you do not have one. | D40: Required
A41: 29 | B41: Notary public arranged (in-person or RON) | C41: Use a local bank, UPS Store, or Remote Online Notarization service. RON accepted as of 2026. | D41: Required
...

Sheet Quick Reference
A1: CAPTUREPILOT · Quick Reference
A2: Key facts, contacts, and links · keep this tab open while you register
A5: KEY FACTS
B6: Cost | C6: $0 — registration is always free. Never pay a third party.
B7: UEI format | C7: 12-character alphanumeric (e.g. A1B2C3D4E5F6)
B8: CAGE code | C8: Assigned automatically for U.S. entities within 3-5 business days
B9: Activation timeline | C9: 10-14 business days after complete submission + notarized letter
B10: Registration validity | C10: 365 days — must renew annually
B11: Renewal window | C11: Opens 60 days before expiration. Renew early.
B12: Notarized letter | C12: Submit to FSD.gov the same day you register. Do not wait for a reminder.
B13: 2FA method | C13: Use authenticator app, not SMS text messages
B14: Address requirement | C14: Physical street address only. PO Boxes are rejected.
B15: IRS name match | C15: Must match IRS records exactly including commas and punctuation
A16: CONTACTS & LINKS
B17: SAM.gov registration | C17: sam.gov/content/entity-registration
B18: Federal Service Desk | C18: fsd.gov · Phone: 866-606-8220 · M-F 8 AM to 8 PM ET
B19: login.gov | C19: login.gov/create-an-account
B20: IRS Letter 147C | C20: Call 1-800-829-4933 > Option 1 > Option 3
B21: SBA size standards | C21: sba.gov/federal-contracting/contracting-guide/size-standards
B22: SBA Certify (8a, HUBZone, WOSB) | C22: certify.sba.gov
B23: VA CVE (SDVOSB) | C23: veteransmallbizce.va.gov
B24: NAICS code lookup | C24: census.gov/naics
B25: PSC manual | C25: acquisition.gov/psc-manual
B26: CapturePilot daily matches | C26: capturepilot.com
A27: REGISTRATION STATUS GUIDE
B28: Draft | C28: You started but have not submitted. Session expires in 30 days.
B29: Submitted | C29: In review queue. Do not bid on contracts yet.
B30: Work in Progress | C30: A reviewer flagged an issue. Check your email immediately.
B31: Active | C31: Registration complete. You can now bid on federal contracts.
B32: Expired | C32: Renewal overdue. Renew immediately. Active contracts may be paused.

Sheet Timeline
A1: CAPTUREPILOT · Registration Timeline — 10 to 14 Business Days
A2: Track your progress · check sam.gov daily until status shows ACTIVE
B4: Set your kickoff date below. Estimated dates auto-calculate from it.
B5: Kickoff date: | C5: 46178.894
A6: # | B6: Phase | C6: Action | D6: Est. Time | E6: Est. Date | F6: Notes / What to Watch For
A7: 1 | B7: Before Day 1 | C7: Gather all documents from Pre-Registration Checklist | D7: 60-90 min | E7: =WORKDAY(KickoffDate, -7) | F7: Complete the Checklist tab fully before opening SAM.gov.
A8: 2 | B8: Before Day 1 | C8: Create login.gov account, enable 2FA, verify identity | D8: 30-60 min | E8: =WORKDAY(KickoffDate, -5) | F8: Use authenticator app for 2FA. Have your photo ID ready.
A9: 3 | B9: Before Day 1 | C9: Download Notarized Letter template from FSD.gov | D9: 15 min | E9: =WORKDAY(KickoffDate, -3) | F9: Download fresh each time — only use the current official template.
A10: 4 | B10: Day 1 | C10: Start entity registration at sam.gov | D10: 45-90 min | E10: =WORKDAY(KickoffDate, 0) | F10: Save progress frequently. The session times out after inactivity.
A11: 5 | B11: Day 1 | C11: UEI auto-generated after EIN validates | D11: Same day | E11: =WORKDAY(KickoffDate, 0) | F11: Save your UEI immediately. Use it on all proposals going forward.
A12: 6 | B12: Day 1 | C12: Complete and notarize Entity Administrator Letter | D12: 1-3 hours | E12: =WORKDAY(KickoffDate, 1) | F12: RON (Remote Online Notarization) accepted as of 2026.
A13: 7 | B13: Day 1 | C13: Submit Notarized Letter to FSD.gov as a case | D13: 15 min | E13: =WORKDAY(KickoffDate, 1) | F13: Save your FSD case number. This is your tracking ID.
A14: 8 | B14: Days 1-2 | C14: IRS validates EIN against legal business name | D14: 1-2 biz days | E14: =WORKDAY(KickoffDate, 2) | F14: If rejected, check name match against IRS Letter 147C exactly.
A15: 9 | B15: Days 3-5 | C15: CAGE Code assigned automatically by DLA | D15: 3-5 biz days | E15: =WORKDAY(KickoffDate, 5) | F15: No action needed. Happens in the background.
A16: 10 | B16: Days 3-7 | C16: FSD reviews and processes Notarized Letter | D16: 3-7 biz days | E16: =WORKDAY(KickoffDate, 7) | F16: Call 866-606-8220 with your case number if no update after 7 days.
A17: 11 | B17: Days 7-14 | C17: Federal review and final activation processing | D17: 7-10 biz days | E17: =WORKDAY(KickoffDate, 11) | F17: Check sam.gov daily. Status changes to ACTIVE when complete.
A18: 12 | B18: Day 10-14 | C18: Status changes to ACTIVE — registration complete | D18: Done! | E18: =WORKDAY(KickoffDate, 14) | F18: You can now respond to opportunities and receive contract awards.
A19: 13 | B19: Day 14+ | C19: Set annual renewal reminder on your calendar | D19: 5 min | E19: =WORKDAY(KickoffDate, 15) | F19: Renewal window opens 60 days before your expiration date.

Sheet Instructions
A1: CAPTUREPILOT · How to use this workbook
A2: Five tabs · one job · cuts the SAM.gov error rate in half
A5: What this is
B6: A pre-flight checklist for SAM.gov entity registration. You collect everything on the Checklist tab BEFORE opening sam.gov. The Dashboard tab tells you when you are actually ready to start.
A7: The five tabs
B8: Dashboard — auto-calculated readiness score. Updates the moment you change a status on Checklist. Green when every required item is Done.
B9: Checklist — the working surface. 35 items across 8 sections. Set each "My Status" dropdown to Done, Need to get, or N/A.
B10: Quick Reference — every link, phone number, and fact you will need while filling out SAM.gov. Open this tab in a second window during registration.
B11: Timeline — set your kickoff date, the estimated dates for each phase recalculate automatically using WORKDAY (business days only).
B12: Instructions — this tab. Read it once.
A13: Workflow we recommend
B14: 1. Open the Checklist tab. Walk every row, set status to Done or Need to get. Assign an owner in the rightmost column if you are doing this with a team.
B15: 2. Check the Dashboard. Aim for 100% on the "Required-Only Completion" gauge before touching sam.gov. Items marked Recommended or If applicable do not block readiness.
B16: 3. Open Timeline, set your kickoff date in the green cell. The estimated dates show when each phase should complete.
B17: 4. Open sam.gov, register with the Quick Reference tab pinned in a second window.
A18: Why we built it this way
B19: I ran SAM.gov registrations for small businesses for two years before building CapturePilot. Same rejection reasons every time — EIN name mismatch by one comma, address listed as a PO Box, notary seal too blurry to scan. All preventable with a checklist done first. This is that checklist.
B20: A typical first-time SAM registration takes 10 to 14 business days from submission to ACTIVE. Add another 7 to 10 days if any document gets bounced. Get the documents right on the first try and you save two weeks.
A21: Compatibility
B22: Built to work in Microsoft Excel 2016+, Excel for Mac, Excel Online, and Google Sheets. All formulas avoid LAMBDA, XLOOKUP, and FILTER so older Excel does not choke. Dropdowns and conditional formatting survive both editors.
A23: Need more help
B24: Call the Federal Service Desk at 866-606-8220 (M-F 8 AM to 8 PM ET) or submit a case at fsd.gov. Both are free. For ongoing daily opportunity matches once you are registered, use capturepilot.com.
