Workbook

Sheet Instructions
B1: CAPTURE MATURITY SELF-AUDIT — INSTRUCTIONS
B3: What this is | C3: A diagnostic for small federal contractors. Rate seven capture domains 0-4. The workbook calculates a weighted maturity score and tells you where to focus first.
B4: Time required | C4: About 25 to 40 minutes if you're honest. Most founders try to rush it and end up grading themselves 3s across the board. Don't.
B5: How to use it | C5: 1) Open the Self-Audit tab. 2) Pick a score 0-4 for every practice using the dropdown. 3) Check the Score Dashboard for your weighted total and tier. 4) Open Action Plan and start working the items the dashboard flagged red.
B6: Scoring rubric | C6: 0 = Not in place. 1 = We know we should, we don't. 2 = Partially in place, inconsistent. 3 = Consistently doing it. 4 = Documented, repeatable, you could show evidence in a DCAA audit or due diligence review.
B7: When to retake it | C7: Quarterly is the sweet spot. Re-score before each color review or before submitting a major proposal. Track movement — a stuck '2' across two quarters means you have a process problem, not a knowledge problem.
B8: Who fills it out | C8: Founder plus capture/BD lead, separately. Compare answers. If you score yourself 4 on Past Performance and your BD lead scores 1, that gap is the story.
B9: What 'Best practice' actually means | C9: A '4' is rare. If you have to think hard about whether you've ever done the thing, you're at 2. If you do it but it lives in one person's head, that's a 3. A 4 has a written SOP, a named owner, and evidence.
B10: About the benchmark target | C10: We set 75% as the target for each domain. That's the median for firms with 3+ years of federal wins and a deliberate capture function. Below 40% is normal for first-year contractors. Don't beat yourself up — just work the plan.
B11: Voice note | C11: We wrote this for a business owner with a contract due in six months and zero government experience. If a question is unclear, the wording is on us, not you. Email Andre at info@capturepilot.com.
B13: THE SEVEN DOMAINS (and why they're weighted that way)
B14: Market Intelligence (15%) | C14: Do you know what's coming six to twelve months out, and who's likely to win it?
B15: Pipeline & Capture Management (20%) | C15: Highest weight. Capture work done early — six to nine months before RFP — is the single biggest driver of win rate.
B16: Relationship Building (15%) | C16: If you're meeting the KO for the first time at the proposal kickoff, you're already losing.
B17: Proposal Quality (20%) | C17: Tied for highest weight. Includes color team reviews, compliance, and pricing discipline. This is where good capture work goes to die if your proposal team is sloppy.
B18: Past Performance (15%) | C18: Federal evaluators read CPARS before they read your prose. A library of structured, RFP-ready references is non-negotiable.
B19: Compliance & Certifications (10%) | C19: Lower weight only because it's binary — either your SAM registration is current or it isn't. But if you score 0 here, nothing else matters.
B20: BD Infrastructure (5%) | C20: The plumbing. CRM, written BD strategy, separate cost pool. Small weight because tools don't win contracts. People who use them do.

Sheet Self-Audit
B1: CAPTURE MATURITY SELF-AUDIT — score each practice 0 to 4
B2: Check the box in the Done column when a practice is in place and you can show evidence. Google Sheets renders these as native checkboxes. Excel 365: right-click > Format Cell > Checkbox to convert. Older Excel shows them as TRUE/FALSE dropdowns — same result. Each checkbox counts 1 point toward the domain total.
B3: Domain / Practice | C3: Done? | D3: Pts | E3: Domain % | F3: Tier | G3: Priority | H3: Notes
B4: MARKET INTELLIGENCE (Weight: 15%)
B5: We have a documented target agency list with 6 to 12 months of pipeline visibility. | C5: FALSE | D5: 1 | E5: =IFERROR(--C5/D5,0) -> 0 | F5: =IF(C5=TRUE,"In place","Not yet") -> Not yet | G5: =IF(C5=TRUE,"","FIX") -> FIX
B6: We monitor SAM.gov daily and have alerts set for our NAICS codes. | C6: FALSE | D6: 1 | E6: =IFERROR(--C6/D6,0) -> 0 | F6: =IF(C6=TRUE,"In place","Not yet") -> Not yet | G6: =IF(C6=TRUE,"","FIX") -> FIX
B7: We track incumbent contract expiration dates for opportunities we want to recompete. | C7: FALSE | D7: 1 | E7: =IFERROR(--C7/D7,0) -> 0 | F7: =IF(C7=TRUE,"In place","Not yet") -> Not yet | G7: =IF(C7=TRUE,"","FIX") -> FIX
B8: We have researched at least 3 competitors' rates, capabilities, and past performance. | C8: FALSE | D8: 1 | E8: =IFERROR(--C8/D8,0) -> 0 | F8: =IF(C8=TRUE,"In place","Not yet") -> Not yet | G8: =IF(C8=TRUE,"","FIX") -> FIX
B9: We understand our top agencies' strategic plans and mission priorities. | C9: FALSE | D9: 1 | E9: =IFERROR(--C9/D9,0) -> 0 | F9: =IF(C9=TRUE,"In place","Not yet") -> Not yet | G9: =IF(C9=TRUE,"","FIX") -> FIX
B10: We know which GWACs and IDIQs our target agencies prefer, and why. | C10: FALSE | D10: 1 | E10: =IFERROR(--C10/D10,0) -> 0 | F10: =IF(C10=TRUE,"In place","Not yet") -> Not yet | G10: =IF(C10=TRUE,"","FIX") -> FIX
B11: MARKET INTELLIGENCE — Domain Total | C11: =SUM(C5:C10) | D11: =SUM(D5:D10) | E11: =IFERROR(C11/D11,0) | F11: =IF(E11>=0.85,"Optimized",IF(E11>=0.70,"Strong",IF(E11>=0.40,"Progressing","Developing"))) | G11: =IF(E11<0.40,"PRIORITY","")
B12: PIPELINE & CAPTURE MANAGEMENT (Weight: 20%)
B13: We maintain a written pipeline with probability of win (PWin) scores per opportunity. | C13: FALSE | D13: 1 | E13: =IFERROR(--C13/D13,0) -> 0 | F13: =IF(C13=TRUE,"In place","Not yet") -> Not yet | G13: =IF(C13=TRUE,"","FIX") -> FIX
B14: We use a documented bid / no-bid process — not gut feel. | C14: FALSE | D14: 1 | E14: =IFERROR(--C14/D14,0) -> 0 | F14: =IF(C14=TRUE,"In place","Not yet") -> Not yet | G14: =IF(C14=TRUE,"","FIX") -> FIX
B15: We start capture activities at least 6 to 9 months before RFP release. | C15: FALSE | D15: 1 | E15: =IFERROR(--C15/D15,0) -> 0 | F15: =IF(C15=TRUE,"In place","Not yet") -> Not yet | G15: =IF(C15=TRUE,"","FIX") -> FIX
B16: We track time invested per pursuit and compare against win rates. | C16: FALSE | D16: 1 | E16: =IFERROR(--C16/D16,0) -> 0 | F16: =IF(C16=TRUE,"In place","Not yet") -> Not yet | G16: =IF(C16=TRUE,"","FIX") -> FIX
B17: We have a defined capture stage gate process (market research, pre-sol, RFP, proposal). | C17: FALSE | D17: 1 | E17: =IFERROR(--C17/D17,0) -> 0 | F17: =IF(C17=TRUE,"In place","Not yet") -> Not yet | G17: =IF(C17=TRUE,"","FIX") -> FIX
B18: We conduct win / loss analyses on every submitted proposal. | C18: FALSE | D18: 1 | E18: =IFERROR(--C18/D18,0) -> 0 | F18: =IF(C18=TRUE,"In place","Not yet") -> Not yet | G18: =IF(C18=TRUE,"","FIX") -> FIX
B19: PIPELINE & CAPTURE MANAGEMENT — Domain Total | C19: =SUM(C13:C18) | D19: =SUM(D13:D18) | E19: =IFERROR(C19/D19,0) | F19: =IF(E19>=0.85,"Optimized",IF(E19>=0.70,"Strong",IF(E19>=0.40,"Progressing","Developing"))) | G19: =IF(E19<0.40,"PRIORITY","")
B20: RELATIONSHIP BUILDING (Weight: 15%)
B21: We have established relationships with at least 2 KOs or CORs at target agencies. | C21: FALSE | D21: 1 | E21: =IFERROR(--C21/D21,0) -> 0 | F21: =IF(C21=TRUE,"In place","Not yet") -> Not yet | G21: =IF(C21=TRUE,"","FIX") -> FIX
B22: We regularly attend industry days, sources sought events, and agency briefings. | C22: FALSE | D22: 1 | E22: =IFERROR(--C22/D22,0) -> 0 | F22: =IF(C22=TRUE,"In place","Not yet") -> Not yet | G22: =IF(C22=TRUE,"","FIX") -> FIX
B23: We've had at least one capability briefing with a target agency in the past 6 months. | C23: FALSE | D23: 1 | E23: =IFERROR(--C23/D23,0) -> 0 | F23: =IF(C23=TRUE,"In place","Not yet") -> Not yet | G23: =IF(C23=TRUE,"","FIX") -> FIX
B24: We have a defined outreach cadence — not just responding to solicitations. | C24: FALSE | D24: 1 | E24: =IFERROR(--C24/D24,0) -> 0 | F24: =IF(C24=TRUE,"In place","Not yet") -> Not yet | G24: =IF(C24=TRUE,"","FIX") -> FIX
B25: We maintain relationships with at least 2 large primes as a potential sub. | C25: FALSE | D25: 1 | E25: =IFERROR(--C25/D25,0) -> 0 | F25: =IF(C25=TRUE,"In place","Not yet") -> Not yet | G25: =IF(C25=TRUE,"","FIX") -> FIX
B26: We attend at least one small business networking event per quarter. | C26: FALSE | D26: 1 | E26: =IFERROR(--C26/D26,0) -> 0 | F26: =IF(C26=TRUE,"In place","Not yet") -> Not yet | G26: =IF(C26=TRUE,"","FIX") -> FIX
B27: RELATIONSHIP BUILDING — Domain Total | C27: =SUM(C21:C26) | D27: =SUM(D21:D26) | E27: =IFERROR(C27/D27,0) | F27: =IF(E27>=0.85,"Optimized",IF(E27>=0.70,"Strong",IF(E27>=0.40,"Progressing","Developing"))) | G27: =IF(E27<0.40,"PRIORITY","")
B28: PROPOSAL QUALITY (Weight: 20%)
B29: We have a written proposal development process with roles and timelines. | C29: FALSE | D29: 1 | E29: =IFERROR(--C29/D29,0) -> 0 | F29: =IF(C29=TRUE,"In place","Not yet") -> Not yet | G29: =IF(C29=TRUE,"","FIX") -> FIX
B30: We conduct internal color team reviews (Pink, Red, Gold) before submission. | C30: FALSE | D30: 1 | E30: =IFERROR(--C30/D30,0) -> 0 | F30: =IF(C30=TRUE,"In place","Not yet") -> Not yet | G30: =IF(C30=TRUE,"","FIX") -> FIX
B31: Our proposals consistently address evaluation criteria in the order listed in the RFP. | C31: FALSE | D31: 1 | E31: =IFERROR(--C31/D31,0) -> 0 | F31: =IF(C31=TRUE,"In place","Not yet") -> Not yet | G31: =IF(C31=TRUE,"","FIX") -> FIX
B32: We use past performance references that are directly relevant to the requirement. | C32: FALSE | D32: 1 | E32: =IFERROR(--C32/D32,0) -> 0 | F32: =IF(C32=TRUE,"In place","Not yet") -> Not yet | G32: =IF(C32=TRUE,"","FIX") -> FIX
B33: Our pricing is informed by competitor analysis, not just cost-plus to margin. | C33: FALSE | D33: 1 | E33: =IFERROR(--C33/D33,0) -> 0 | F33: =IF(C33=TRUE,"In place","Not yet") -> Not yet | G33: =IF(C33=TRUE,"","FIX") -> FIX
B34: We comply fully with Section L and M — page limits, font, format, submission method. | C34: FALSE | D34: 1 | E34: =IFERROR(--C34/D34,0) -> 0 | F34: =IF(C34=TRUE,"In place","Not yet") -> Not yet | G34: =IF(C34=TRUE,"","FIX") -> FIX
B35: PROPOSAL QUALITY — Domain Total | C35: =SUM(C29:C34) | D35: =SUM(D29:D34) | E35: =IFERROR(C35/D35,0) | F35: =IF(E35>=0.85,"Optimized",IF(E35>=0.70,"Strong",IF(E35>=0.40,"Progressing","Developing"))) | G35: =IF(E35<0.40,"PRIORITY","")
B36: PAST PERFORMANCE (Weight: 15%)
B37: We maintain a library of past performance references in a structured format. | C37: FALSE | D37: 1 | E37: =IFERROR(--C37/D37,0) -> 0 | F37: =IF(C37=TRUE,"In place","Not yet") -> Not yet | G37: =IF(C37=TRUE,"","FIX") -> FIX
B38: We have at least 3 directly relevant federal contracts (or strong commercial analogues). | C38: FALSE | D38: 1 | E38: =IFERROR(--C38/D38,0) -> 0 | F38: =IF(C38=TRUE,"In place","Not yet") -> Not yet | G38: =IF(C38=TRUE,"","FIX") -> FIX
B39: We collect CPARS / PPIRS ratings and know our scores. | C39: FALSE | D39: 1 | E39: =IFERROR(--C39/D39,0) -> 0 | F39: =IF(C39=TRUE,"In place","Not yet") -> Not yet | G39: =IF(C39=TRUE,"","FIX") -> FIX
B40: We proactively manage government POC relationships on active contracts. | C40: FALSE | D40: 1 | E40: =IFERROR(--C40/D40,0) -> 0 | F40: =IF(C40=TRUE,"In place","Not yet") -> Not yet | G40: =IF(C40=TRUE,"","FIX") -> FIX
...

Sheet Score Dashboard
B1: CAPTURE MATURITY DASHBOARD — auto-calculated from Self-Audit
B3: Domain | C3: Weight | D3: Your Score % | E3: Weighted Contribution | F3: Benchmark | G3: Gap | H3: Recommended Focus Area
B4: MARKET INTELLIGENCE | C4: 0.15 | D4: ='Self-Audit'!E11 | E4: =C4*D4 | F4: 0.75 | G4: =F4-D4 | H4: =IF(D4<0.40,"Build agency target list; set SAM.gov alerts; pull FPDS incumbent data on top 5 contracts.","On track — maintain")
B5: PIPELINE & CAPTURE MANAGEMENT | C5: 0.2 | D5: ='Self-Audit'!E19 | E5: =C5*D5 | F5: 0.75 | G5: =F5-D5 | H5: =IF(D5<0.40,"Implement a stage-gate capture process; start pursuits at 6+ months pre-RFP; require PWin per row.","On track — maintain")
B6: RELATIONSHIP BUILDING | C6: 0.15 | D6: ='Self-Audit'!E27 | E6: =C6*D6 | F6: 0.75 | G6: =F6-D6 | H6: =IF(D6<0.40,"Book 2 OSDBU briefings this quarter; attend industry days consistently; build 2 prime relationships.","On track — maintain")
B7: PROPOSAL QUALITY | C7: 0.2 | D7: ='Self-Audit'!E35 | E7: =C7*D7 | F7: 0.75 | G7: =F7-D7 | H7: =IF(D7<0.40,"Install color team reviews; build a Section L/M compliance matrix template; price to win, not to margin.","On track — maintain")
B8: PAST PERFORMANCE | C8: 0.15 | D8: ='Self-Audit'!E43 | E8: =C8*D8 | F8: 0.75 | G8: =F8-D8 | H8: =IF(D8<0.40,"Build 5 structured PP write-ups (CPARS format); collect every CPARS score on file.","On track — maintain")
B9: COMPLIANCE & CERTIFICATIONS | C9: 0.1 | D9: ='Self-Audit'!E51 | E9: =C9*D9 | F9: 0.75 | G9: =F9-D9 | H9: =IF(D9<0.40,"Renew SAM; verify certifications; document COI process; review NAICS size standards.","On track — maintain")
B10: BD INFRASTRUCTURE | C10: 0.05 | D10: ='Self-Audit'!E57 | E10: =C10*D10 | F10: 0.75 | G10: =F10-D10 | H10: =IF(D10<0.40,"Write the BD strategy; install a CRM; refresh the capability statement per top agency.","On track — maintain")
B11: OVERALL MATURITY SCORE | C11: =SUM(C4:C10) | D11: =SUMPRODUCT(C4:C10,D4:D10)/SUM(C4:C10) | E11: =SUM(E4:E10) | F11: =0.75 | G11: =F11-D11 | H11: =IF(D11>=0.85,"Optimized — keep refining",IF(D11>=0.70,"Strong — work the gaps",IF(D11>=0.40,"Progressing — pick 3 priorities","Developing — work the 30-day plan")))
B13: MATURITY LEVEL INTERPRETATION
B14: 0 to 39% | C14: Developing | D14: Capture is ad hoc. You respond to solicitations as they appear, without a system. Win rates are low and unpredictable — typically under 10%.
B15: 40 to 69% | C15: Progressing | D15: Some practices in place, but inconsistent. Win rates are improving and depend heavily on one or two people's effort. A bus problem.
B16: 70 to 84% | C16: Strong | D16: Capture is documented, consistent, and showing results. You win competitively and can articulate why. Win rate usually 25-40%.
B17: 85 to 100% | C17: Optimized | D17: Capture is a competitive advantage. You shape requirements, you have agency relationships, and your win rate consistently clears 40%.
B19: YOUR CURRENT TIER | D19: =IF(D11>=0.85,"OPTIMIZED",IF(D11>=0.70,"STRONG",IF(D11>=0.40,"PROGRESSING","DEVELOPING")))
B21: TOP 3 PRIORITY DOMAINS (lowest score first)
B22: #1 | C22: =INDEX(B4:B10,MATCH(SMALL(D4:D10,1),D4:D10,0)) | D22: =SMALL(D4:D10,1) | E22: =INDEX(H4:H10,MATCH(SMALL(D4:D10,1),D4:D10,0))
B23: #2 | C23: =INDEX(B4:B10,MATCH(SMALL(D4:D10,2),D4:D10,0)) | D23: =SMALL(D4:D10,2) | E23: =INDEX(H4:H10,MATCH(SMALL(D4:D10,2),D4:D10,0))
B24: #3 | C24: =INDEX(B4:B10,MATCH(SMALL(D4:D10,3),D4:D10,0)) | D24: =SMALL(D4:D10,3) | E24: =INDEX(H4:H10,MATCH(SMALL(D4:D10,3),D4:D10,0))

Sheet Action Plan
B1: 30 / 60 / 90 DAY ACTION PLAN — translate the audit into work
B2: Pre-loaded with the most common starter actions. Edit, delete, add your own. Set the Status column to Complete as you finish each one — the bar at the bottom tracks your completion rate.
B3: Action Item | C3: Domain | D3: Window | E3: Owner | F3: Due Date | G3: Priority | H3: Status | I3: Done?
B4: Set SAM.gov email alerts for top 3 NAICS codes | C4: Market Intelligence | D4: 30 days | G4: High | H4: Not Started | I4: =IF(H4="Complete","Yes","")
B5: Pull FPDS data on top 5 incumbent contracts in our space | C5: Market Intelligence | D5: 30 days | G5: High | H5: Not Started | I5: =IF(H5="Complete","Yes","")
B6: Verify SAM.gov registration is active and every NAICS code is current | C6: Compliance | D6: 30 days | G6: Critical | H6: Not Started | I6: =IF(H6="Complete","Yes","")
B7: Create a one-page pipeline tracker with PWin scores per pursuit | C7: Pipeline & Capture | D7: 30 days | G7: Critical | H7: Not Started | I7: =IF(H7="Complete","Yes","")
B8: Refresh capability statement — one page, mission-aligned, per top agency | C8: BD Infrastructure | D8: 30 days | G8: High | H8: Not Started | I8: =IF(H8="Complete","Yes","")
B9: Write a bid / no-bid scoring matrix for any opportunity over $500K | C9: Pipeline & Capture | D9: 30 days | G9: High | H9: Not Started | I9: =IF(H9="Complete","Yes","")
B10: Book a capability briefing with at least 1 target agency OSDBU or KO | C10: Relationships | D10: 60 days | G10: High | H10: Not Started | I10: =IF(H10="Complete","Yes","")
B11: Write 3 structured past performance references in CPARS format | C11: Past Performance | D11: 60 days | G11: High | H11: Not Started | I11: =IF(H11="Complete","Yes","")
B12: Pull competitor labor rates from GSA CALC for top 5 categories | C12: Market Intelligence | D12: 60 days | G12: Medium | H12: Not Started | I12: =IF(H12="Complete","Yes","")
B13: Template your standard proposal outline mapped to Section L and M | C13: Proposal Quality | D13: 60 days | G13: High | H13: Not Started | I13: =IF(H13="Complete","Yes","")
B14: Identify 2 large primes to pursue teaming relationships with | C14: Relationships | D14: 60 days | G14: Medium | H14: Not Started | I14: =IF(H14="Complete","Yes","")
B15: Collect every current CPARS rating and document performance scores | C15: Past Performance | D15: 60 days | G15: High | H15: Not Started | I15: =IF(H15="Complete","Yes","")
... B21: Attend at least 2 agency industry days or small business events | C21: Relationships | D21: 90 days | G21: Medium | H21: Not Started | I21: =IF(H21="Complete","Yes","")
B23: COMPLETION SUMMARY
B24: Total actions | C24: =COUNTA(B4:B21)
B25: Completed | C25: =COUNTIF(H4:H21,"Complete")
B26: In progress | C26: =COUNTIF(H4:H21,"In Progress")
B27: Blocked | C27: =COUNTIF(H4:H21,"Blocked")
B28: Not started | C28: =COUNTIF(H4:H21,"Not Started")
B29: Completion rate | C29: =IFERROR(COUNTIF(H4:H21,"Complete")/COUNTA(B4:B21),0)
B31: Priority key: Critical = this week. High = this month. Medium = this quarter. Low = next quarter. Status options: Not Started, In Progress, Blocked, Complete.

Sheet Help & Examples
B1: WHAT A '3' VS A '4' ACTUALLY LOOKS LIKE
B3: Domain | C3: Score 3 (Consistent) | D3: Score 4 (Documented + Provable)
B4: Market Intelligence | C4: Founder checks SAM.gov a few times a week, knows the top 5 incumbents by name. | D4: Daily SAM alerts firing into Slack; FPDS pull on incumbents refreshed monthly; written agency target list with PWin estimates.
B5: Pipeline & Capture | C5: Spreadsheet pipeline with deals and dates. Bid/no-bid decided in a Tuesday meeting. | D5: Stage-gated capture in CRM; PWin scored per row; written bid/no-bid rubric with go/no-go criteria; capture starts 6+ months pre-RFP for any deal over $500K.
B6: Relationship Building | C6: You've met a couple of KOs at conferences. You know who they are. | D6: Quarterly cadence of capability briefings; documented relationship map per agency; teaming agreements signed with 2+ primes.
B7: Proposal Quality | C7: You do a final read-through before submitting. Compliance matrix is in your head. | D7: Color reviews (Pink, Red, Gold) on every proposal over $250K; written Section L/M compliance matrix per submission; price-to-win analysis on file.
B8: Past Performance | C8: You have a folder of past contracts and can pull a reference when asked. | D8: Library of structured PP write-ups (5+) ready to drop into any proposal; CPARS scores tracked; lessons learned captured on every closeout.
B9: Compliance | C9: SAM is current. You think your NAICS codes are right. | D9: SAM updated within 12 months; NAICS reviewed quarterly; size standard verified per code; OCI policy written and signed.
B10: BD Infrastructure | C10: You use Google Sheets for the pipeline. Capability statement was last updated 'recently'. | D10: Real CRM (HubSpot, Salesforce, or a federal-specific tool); BD strategy in writing with annual targets; capability statement refreshed quarterly per top agency.
B12: COMMON HONEST-ASSESSMENT MISTAKES
B13: Scoring 3 for 'I know how to' | C13: Knowing how to do something and consistently doing it are different. If you've done it on one proposal, that's a 2, not a 3.
B14: Scoring 4 because 'we always do it' | C14: If it's not written down, somebody leaves and it's gone. A '4' requires documentation.
B15: Scoring 0 as 'rare' | C15: 0 means it's not in place at all. If you've ever done it once on purpose, you're at 1 or 2.
B16: Averaging founder + BD lead scores | C16: Don't. Compare them side by side — the gap itself is the diagnostic.
